Workbook

Sheet Data
C2: =TEXT((C3&" "&C4),"MMm-YY") -> Jul-24 | J2: Copyright: Veera Seaman
B3: Select month to view: | C3: July
B4: Select year to view: | C4: 2024
B7: Month and year | C7: =IF(ISBLANK($C$2),"",(TEXT(($C$2),"mmm-yy"))) -> Jul-24 | D7: =(TEXT(DATE(YEAR(C7),MONTH(C7)+1,DAY(C7)),"MMM-YY")) -> Aug-24 | E7: =(TEXT(DATE(YEAR(D7),MONTH(D7)+1,DAY(D7)),"MMM-YY")) -> Sep-24 | F7: =(TEXT(DATE(YEAR(E7),MONTH(E7)+1,DAY(E7)),"MMM-YY")) -> Oct-24 | G7: =(TEXT(DATE(YEAR(F7),MONTH(F7)+1,DAY(F7)),"MMM-YY")) -> Nov-24 | H7: =(TEXT(DATE(YEAR(G7),MONTH(G7)+1,DAY(G7)),"MMM-YY")) -> Dec-24 | I7: =(TEXT(DATE(YEAR(H7),MONTH(H7)+1,DAY(H7)),"MMM-YY")) -> Jan-25 | J7: =(TEXT(DATE(YEAR(I7),MONTH(I7)+1,DAY(I7)),"MMM-YY")) -> Feb-25 | K7: =(TEXT(DATE(YEAR(J7),MONTH(J7)+1,DAY(J7)),"MMM-YY")) -> Mar-25 | ... M7: =(TEXT(DATE(YEAR(L7),MONTH(L7)+1,DAY(L7)),"MMM-YY")) -> May-25 | P7: =IFERROR(IF(DATEVALUE(M7)>=DATEVALUE($EF$1),"",(TEXT(DATE(YEAR(M7),MONTH(M7)+1,DAY(M7)),"MMM-YY"))),"") | Q7: =IFERROR(IF(DATEVALUE(P7)>=DATEVALUE($EF$1),"",(TEXT(DATE(YEAR(P7),MONTH(P7)+1,DAY(P7)),"MMM-YY"))),"")
B8: KPI 28 % | C8: =IF(ISBLANK($C$2),"",(IFERROR(INDEX(Raw!$C$1:$EE$33,MATCH($B8,Raw!$C$1:$C$33,0),MATCH(C7,Raw!$C$1:$EE$1,0)),""))) -> 1.4237531 | D8: =IF(ISBLANK($C$2),"",(IFERROR(INDEX(Raw!$C$1:$EE$33,MATCH($B8,Raw!$C$1:$C$33,0),MATCH(D7,Raw!$C$1:$EE$1,0)),""))) -> 1.1021254 | E8: =IF(ISBLANK($C$2),"",(IFERROR(INDEX(Raw!$C$1:$EE$33,MATCH($B8,Raw!$C$1:$C$33,0),MATCH(E7,Raw!$C$1:$EE$1,0)),""))) -> 1.4816275 | F8: =IF(ISBLANK($C$2),"",(IFERROR(INDEX(Raw!$C$1:$EE$33,MATCH($B8,Raw!$C$1:$C$33,0),MATCH(F7,Raw!$C$1:$EE$1,0)),""))) -> 1.8536548 | G8: =IF(ISBLANK($C$2),"",(IFERROR(INDEX(Raw!$C$1:$EE$33,MATCH($B8,Raw!$C$1:$C$33,0),MATCH(G7,Raw!$C$1:$EE$1,0)),""))) -> 1.7383785 | H8: =IF(ISBLANK($C$2),"",(IFERROR(INDEX(Raw!$C$1:$EE$33,MATCH($B8,Raw!$C$1:$C$33,0),MATCH(H7,Raw!$C$1:$EE$1,0)),""))) -> 1.9372689 | I8: =IF(ISBLANK($C$2),"",(IFERROR(INDEX(Raw!$C$1:$EE$33,MATCH($B8,Raw!$C$1:$C$33,0),MATCH(I7,Raw!$C$1:$EE$1,0)),""))) -> 1.9906614 | J8: =IF(ISBLANK($C$2),"",(IFERROR(INDEX(Raw!$C$1:$EE$33,MATCH($B8,Raw!$C$1:$C$33,0),MATCH(J7,Raw!$C$1:$EE$1,0)),""))) -> 1.4825801 | ... M8: =IF(ISBLANK($C$2),"",(IFERROR(INDEX(Raw!$C$1:$EE$33,MATCH($B8,Raw!$C$1:$C$33,0),MATCH(M7,Raw!$C$1:$EE$1,0)),""))) -> 1.1379321 | P8: =(IFERROR(INDEX(Raw!$C$1:$EE$33,MATCH(#REF!,Raw!$C$1:$C$33,0),MATCH(P$79,Raw!$C$1:$EE$1,0)),"")) | Q8: =(IFERROR(INDEX(Raw!$C$1:$EE$33,MATCH(#REF!,Raw!$C$1:$C$33,0),MATCH(Q$79,Raw!$C$1:$EE$1,0)),""))
B26: Month and year | C26: =IF(ISBLANK($C$2),"",(TEXT(($C$2),"mmm-yy"))) -> Jul-24 | D26: =(TEXT(DATE(YEAR(C26),MONTH(C26)+1,DAY(C26)),"MMM-YY")) -> Aug-24 | E26: =(TEXT(DATE(YEAR(D26),MONTH(D26)+1,DAY(D26)),"MMM-YY")) -> Sep-24 | F26: =(TEXT(DATE(YEAR(E26),MONTH(E26)+1,DAY(E26)),"MMM-YY")) -> Oct-24 | G26: =(TEXT(DATE(YEAR(F26),MONTH(F26)+1,DAY(F26)),"MMM-YY")) -> Nov-24 | H26: =(TEXT(DATE(YEAR(G26),MONTH(G26)+1,DAY(G26)),"MMM-YY")) -> Dec-24 | I26: =(TEXT(DATE(YEAR(H26),MONTH(H26)+1,DAY(H26)),"MMM-YY")) -> Jan-25 | J26: =(TEXT(DATE(YEAR(I26),MONTH(I26)+1,DAY(I26)),"MMM-YY")) -> Feb-25 | K26: =(TEXT(DATE(YEAR(J26),MONTH(J26)+1,DAY(J26)),"MMM-YY")) -> Mar-25 | ... M26: =(TEXT(DATE(YEAR(L26),MONTH(L26)+1,DAY(L26)),"MMM-YY")) -> May-25 | P26: =IFERROR(IF(DATEVALUE(M26)>=DATEVALUE($EF$1),"",(TEXT(DATE(YEAR(M26),MONTH(M26)+1,DAY(M26)),"MMM-YY"))),"") | Q26: =IFERROR(IF(DATEVALUE(P26)>=DATEVALUE($EF$1),"",(TEXT(DATE(YEAR(P26),MONTH(P26)+1,DAY(P26)),"MMM-YY"))),"")
B27: KPI 8 % | C27: =IF(ISBLANK($C$2),"",(IFERROR(INDEX(Raw!$C$1:$EE$33,MATCH($B27,Raw!$C$1:$C$33,0),MATCH(C26,Raw!$C$1:$EE$1,0)),""))) -> 0.65342012 | D27: =IF(ISBLANK($C$2),"",(IFERROR(INDEX(Raw!$C$1:$EE$33,MATCH($B27,Raw!$C$1:$C$33,0),MATCH(D26,Raw!$C$1:$EE$1,0)),""))) -> 0.64553864 | E27: =IF(ISBLANK($C$2),"",(IFERROR(INDEX(Raw!$C$1:$EE$33,MATCH($B27,Raw!$C$1:$C$33,0),MATCH(E26,Raw!$C$1:$EE$1,0)),""))) -> 0.47858841 | F27: =IF(ISBLANK($C$2),"",(IFERROR(INDEX(Raw!$C$1:$EE$33,MATCH($B27,Raw!$C$1:$C$33,0),MATCH(F26,Raw!$C$1:$EE$1,0)),""))) -> 0.068056617 | G27: =IF(ISBLANK($C$2),"",(IFERROR(INDEX(Raw!$C$1:$EE$33,MATCH($B27,Raw!$C$1:$C$33,0),MATCH(G26,Raw!$C$1:$EE$1,0)),""))) -> 0.65742949 | H27: =IF(ISBLANK($C$2),"",(IFERROR(INDEX(Raw!$C$1:$EE$33,MATCH($B27,Raw!$C$1:$C$33,0),MATCH(H26,Raw!$C$1:$EE$1,0)),""))) -> 0.97936445 | I27: =IF(ISBLANK($C$2),"",(IFERROR(INDEX(Raw!$C$1:$EE$33,MATCH($B27,Raw!$C$1:$C$33,0),MATCH(I26,Raw!$C$1:$EE$1,0)),""))) -> 0.26415309 | J27: =IF(ISBLANK($C$2),"",(IFERROR(INDEX(Raw!$C$1:$EE$33,MATCH($B27,Raw!$C$1:$C$33,0),MATCH(J26,Raw!$C$1:$EE$1,0)),""))) -> 0.10239877 | ... M27: =IF(ISBLANK($C$2),"",(IFERROR(INDEX(Raw!$C$1:$EE$33,MATCH($B27,Raw!$C$1:$C$33,0),MATCH(M26,Raw!$C$1:$EE$1,0)),""))) -> 0.23913004 | P27: =(IFERROR(INDEX(Raw!$C$1:$EE$33,MATCH(#REF!,Raw!$C$1:$C$33,0),MATCH(P$79,Raw!$C$1:$EE$1,0)),"")) | Q27: =(IFERROR(INDEX(Raw!$C$1:$EE$33,MATCH(#REF!,Raw!$C$1:$C$33,0),MATCH(Q$79,Raw!$C$1:$EE$1,0)),""))
B45: Month and year | C45: =IF(ISBLANK($C$2),"",(TEXT(($C$2),"mmm-yy"))) -> Jul-24 | D45: =(TEXT(DATE(YEAR(C45),MONTH(C45)+1,DAY(C45)),"MMM-YY")) -> Aug-24 | E45: =(TEXT(DATE(YEAR(D45),MONTH(D45)+1,DAY(D45)),"MMM-YY")) -> Sep-24 | F45: =(TEXT(DATE(YEAR(E45),MONTH(E45)+1,DAY(E45)),"MMM-YY")) -> Oct-24 | G45: =(TEXT(DATE(YEAR(F45),MONTH(F45)+1,DAY(F45)),"MMM-YY")) -> Nov-24 | H45: =(TEXT(DATE(YEAR(G45),MONTH(G45)+1,DAY(G45)),"MMM-YY")) -> Dec-24 | I45: =(TEXT(DATE(YEAR(H45),MONTH(H45)+1,DAY(H45)),"MMM-YY")) -> Jan-25 | J45: =(TEXT(DATE(YEAR(I45),MONTH(I45)+1,DAY(I45)),"MMM-YY")) -> Feb-25 | K45: =(TEXT(DATE(YEAR(J45),MONTH(J45)+1,DAY(J45)),"MMM-YY")) -> Mar-25 | ... M45: =(TEXT(DATE(YEAR(L45),MONTH(L45)+1,DAY(L45)),"MMM-YY")) -> May-25 | P45: =IFERROR(IF(DATEVALUE(M45)>=DATEVALUE($EF$1),"",(TEXT(DATE(YEAR(M45),MONTH(M45)+1,DAY(M45)),"MMM-YY"))),"") | Q45: =IFERROR(IF(DATEVALUE(P45)>=DATEVALUE($EF$1),"",(TEXT(DATE(YEAR(P45),MONTH(P45)+1,DAY(P45)),"MMM-YY"))),"")
B46: KPI 16 % | C46: =IF(ISBLANK($C$2),"",(IFERROR(INDEX(Raw!$C$1:$EE$33,MATCH($B46,Raw!$C$1:$C$33,0),MATCH(C45,Raw!$C$1:$EE$1,0)),""))) -> 0.16516012 | D46: =IF(ISBLANK($C$2),"",(IFERROR(INDEX(Raw!$C$1:$EE$33,MATCH($B46,Raw!$C$1:$C$33,0),MATCH(D45,Raw!$C$1:$EE$1,0)),""))) -> 0.42635973 | E46: =IF(ISBLANK($C$2),"",(IFERROR(INDEX(Raw!$C$1:$EE$33,MATCH($B46,Raw!$C$1:$C$33,0),MATCH(E45,Raw!$C$1:$EE$1,0)),""))) -> 0.077527946 | F46: =IF(ISBLANK($C$2),"",(IFERROR(INDEX(Raw!$C$1:$EE$33,MATCH($B46,Raw!$C$1:$C$33,0),MATCH(F45,Raw!$C$1:$EE$1,0)),""))) -> 0.57783572 | G46: =IF(ISBLANK($C$2),"",(IFERROR(INDEX(Raw!$C$1:$EE$33,MATCH($B46,Raw!$C$1:$C$33,0),MATCH(G45,Raw!$C$1:$EE$1,0)),""))) -> 0.4233348 | H46: =IF(ISBLANK($C$2),"",(IFERROR(INDEX(Raw!$C$1:$EE$33,MATCH($B46,Raw!$C$1:$C$33,0),MATCH(H45,Raw!$C$1:$EE$1,0)),""))) -> 0.65813653 | I46: =IF(ISBLANK($C$2),"",(IFERROR(INDEX(Raw!$C$1:$EE$33,MATCH($B46,Raw!$C$1:$C$33,0),MATCH(I45,Raw!$C$1:$EE$1,0)),""))) -> 0.081254899 | J46: =IF(ISBLANK($C$2),"",(IFERROR(INDEX(Raw!$C$1:$EE$33,MATCH($B46,Raw!$C$1:$C$33,0),MATCH(J45,Raw!$C$1:$EE$1,0)),""))) -> 0.85771781 | ... M46: =IF(ISBLANK($C$2),"",(IFERROR(INDEX(Raw!$C$1:$EE$33,MATCH($B46,Raw!$C$1:$C$33,0),MATCH(M45,Raw!$C$1:$EE$1,0)),""))) -> 0.40253417 | P46: =(IFERROR(INDEX(Raw!$C$1:$EE$33,MATCH(#REF!,Raw!$C$1:$C$33,0),MATCH(P$79,Raw!$C$1:$EE$1,0)),"")) | Q46: =(IFERROR(INDEX(Raw!$C$1:$EE$33,MATCH(#REF!,Raw!$C$1:$C$33,0),MATCH(Q$79,Raw!$C$1:$EE$1,0)),""))
B64: Month and year | C64: =IF(ISBLANK($C$2),"",(TEXT(($C$2),"mmm-yy"))) -> Jul-24 | D64: =(TEXT(DATE(YEAR(C64),MONTH(C64)+1,DAY(C64)),"MMM-YY")) -> Aug-24 | E64: =(TEXT(DATE(YEAR(D64),MONTH(D64)+1,DAY(D64)),"MMM-YY")) -> Sep-24 | F64: =(TEXT(DATE(YEAR(E64),MONTH(E64)+1,DAY(E64)),"MMM-YY")) -> Oct-24 | G64: =(TEXT(DATE(YEAR(F64),MONTH(F64)+1,DAY(F64)),"MMM-YY")) -> Nov-24 | H64: =(TEXT(DATE(YEAR(G64),MONTH(G64)+1,DAY(G64)),"MMM-YY")) -> Dec-24 | I64: =(TEXT(DATE(YEAR(H64),MONTH(H64)+1,DAY(H64)),"MMM-YY")) -> Jan-25 | J64: =(TEXT(DATE(YEAR(I64),MONTH(I64)+1,DAY(I64)),"MMM-YY")) -> Feb-25 | K64: =(TEXT(DATE(YEAR(J64),MONTH(J64)+1,DAY(J64)),"MMM-YY")) -> Mar-25 | ... M64: =(TEXT(DATE(YEAR(L64),MONTH(L64)+1,DAY(L64)),"MMM-YY")) -> May-25 | P64: =IFERROR(IF(DATEVALUE(M64)>=DATEVALUE($EF$1),"",(TEXT(DATE(YEAR(M64),MONTH(M64)+1,DAY(M64)),"MMM-YY"))),"") | Q64: =IFERROR(IF(DATEVALUE(P64)>=DATEVALUE($EF$1),"",(TEXT(DATE(YEAR(P64),MONTH(P64)+1,DAY(P64)),"MMM-YY"))),"")
B65: KPI 8 % | C65: =IF(ISBLANK($C$2),"",(IFERROR(INDEX(Raw!$C$1:$EE$33,MATCH($B65,Raw!$C$1:$C$33,0),MATCH(C64,Raw!$C$1:$EE$1,0)),""))) -> 0.65342012 | D65: =IF(ISBLANK($C$2),"",(IFERROR(INDEX(Raw!$C$1:$EE$33,MATCH($B65,Raw!$C$1:$C$33,0),MATCH(D64,Raw!$C$1:$EE$1,0)),""))) -> 0.64553864 | E65: =IF(ISBLANK($C$2),"",(IFERROR(INDEX(Raw!$C$1:$EE$33,MATCH($B65,Raw!$C$1:$C$33,0),MATCH(E64,Raw!$C$1:$EE$1,0)),""))) -> 0.47858841 | F65: =IF(ISBLANK($C$2),"",(IFERROR(INDEX(Raw!$C$1:$EE$33,MATCH($B65,Raw!$C$1:$C$33,0),MATCH(F64,Raw!$C$1:$EE$1,0)),""))) -> 0.068056617 | G65: =IF(ISBLANK($C$2),"",(IFERROR(INDEX(Raw!$C$1:$EE$33,MATCH($B65,Raw!$C$1:$C$33,0),MATCH(G64,Raw!$C$1:$EE$1,0)),""))) -> 0.65742949 | H65: =IF(ISBLANK($C$2),"",(IFERROR(INDEX(Raw!$C$1:$EE$33,MATCH($B65,Raw!$C$1:$C$33,0),MATCH(H64,Raw!$C$1:$EE$1,0)),""))) -> 0.97936445 | I65: =IF(ISBLANK($C$2),"",(IFERROR(INDEX(Raw!$C$1:$EE$33,MATCH($B65,Raw!$C$1:$C$33,0),MATCH(I64,Raw!$C$1:$EE$1,0)),""))) -> 0.26415309 | J65: =IF(ISBLANK($C$2),"",(IFERROR(INDEX(Raw!$C$1:$EE$33,MATCH($B65,Raw!$C$1:$C$33,0),MATCH(J64,Raw!$C$1:$EE$1,0)),""))) -> 0.10239877 | ... M65: =IF(ISBLANK($C$2),"",(IFERROR(INDEX(Raw!$C$1:$EE$33,MATCH($B65,Raw!$C$1:$C$33,0),MATCH(M64,Raw!$C$1:$EE$1,0)),""))) -> 0.23913004 | P65: =(IFERROR(INDEX(Raw!$C$1:$EE$33,MATCH(#REF!,Raw!$C$1:$C$33,0),MATCH(P$79,Raw!$C$1:$EE$1,0)),"")) | Q65: =(IFERROR(INDEX(Raw!$C$1:$EE$33,MATCH(#REF!,Raw!$C$1:$C$33,0),MATCH(Q$79,Raw!$C$1:$EE$1,0)),""))
K83: Copyright: Veera Seaman

Sheet Lists
C1: Values update automatically! Please only modify if you see an error being indicated.
B2: # | C2: Month | E2: Year | F2: Year calculation | I2: Copyright: Veera Seaman
B3: 0 | C3: =TEXT(TODAY(), "Mmmm") -> September | E3: =TEXT((DATE(YEAR(TODAY())+F3, MONTH(1), DAY(1))), "YYYY") -> 2020 | F3: -5
B4: 1 | C4: =TEXT(DATE(YEAR(TODAY()),MONTH(TODAY())+B4,DAY(TODAY())), "Mmmm") -> October | E4: =TEXT((DATE(YEAR(TODAY())+F4, MONTH(1), DAY(1))), "YYYY") -> 2021 | F4: -4
B5: 2 | C5: =TEXT(DATE(YEAR(TODAY()),MONTH(TODAY())+B5,DAY(TODAY())), "Mmmm") -> November | E5: =TEXT((DATE(YEAR(TODAY())+F5, MONTH(1), DAY(1))), "YYYY") -> 2022 | F5: -3
B6: 3 | C6: =TEXT(DATE(YEAR(TODAY()),MONTH(TODAY())+B6,DAY(TODAY())), "Mmmm") -> December | E6: =TEXT((DATE(YEAR(TODAY())+F6, MONTH(1), DAY(1))), "YYYY") -> 2023 | F6: -2
B7: 4 | C7: =TEXT(DATE(YEAR(TODAY()),MONTH(TODAY())+B7,DAY(TODAY())), "Mmmm") -> January | E7: =TEXT((DATE(YEAR(TODAY())+F7, MONTH(1), DAY(1))), "YYYY") -> 2024 | F7: -1
B8: 5 | C8: =TEXT(DATE(YEAR(TODAY()),MONTH(TODAY())+B8,DAY(TODAY())), "Mmmm") -> February | E8: =TEXT(TODAY(), "YYY") -> 2025 | F8: =IF(E8=TEXT(TODAY(),"YYY"),"Current yr","Check yr in C2") -> Current yr
B9: 6 | C9: =TEXT(DATE(YEAR(TODAY()),MONTH(TODAY())+B9,DAY(TODAY())), "Mmmm") -> March | E9: =TEXT((DATE(YEAR(TODAY())+F9, MONTH(1), DAY(1))), "YYYY") -> 2026 | F9: 1
B10: 7 | C10: =TEXT(DATE(YEAR(TODAY()),MONTH(TODAY())+B10,DAY(TODAY())), "Mmmm") -> April | E10: =TEXT((DATE(YEAR(TODAY())+F10, MONTH(1), DAY(1))), "YYYY") -> 2027 | F10: 2
B11: 8 | C11: =TEXT(DATE(YEAR(TODAY()),MONTH(TODAY())+B11,DAY(TODAY())), "Mmmm") -> May | E11: =TEXT((DATE(YEAR(TODAY())+F11, MONTH(1), DAY(1))), "YYYY") -> 2028 | F11: 3
B12: 9 | C12: =TEXT(DATE(YEAR(TODAY()),MONTH(TODAY())+B12,DAY(TODAY())), "Mmmm") -> June | E12: =TEXT((DATE(YEAR(TODAY())+F12, MONTH(1), DAY(1))), "YYYY") -> 2029 | F12: 4
B13: 10 | C13: =TEXT(DATE(YEAR(TODAY()),MONTH(TODAY())+B13,DAY(TODAY())), "Mmmm") -> July | E13: =TEXT((DATE(YEAR(TODAY())+F13, MONTH(1), DAY(1))), "YYYY") -> 2030 | F13: 5
B14: 11 | C14: =TEXT(DATE(YEAR(TODAY()),MONTH(TODAY())+B14,DAY(TODAY())), "Mmmm") -> August

Sheet Raw
B1: Raw data: | C1: Month and year | D1: =TEXT(DATE(Lists!$E$3, MONTH(1), DAY(1)), "Mmm-YY") -> Jan-20 | E1: =TEXT(DATE(YEAR(D1), MONTH(D1)+1, DAY(D1)), "Mmm-yy") -> Feb-20 | F1: =TEXT(DATE(YEAR(E1), MONTH(E1)+1, DAY(E1)), "Mmm-yy") -> Mar-20 | G1: =TEXT(DATE(YEAR(F1), MONTH(F1)+1, DAY(F1)), "Mmm-yy") -> Apr-20 | H1: =TEXT(DATE(YEAR(G1), MONTH(G1)+1, DAY(G1)), "Mmm-yy") -> May-20 | I1: =TEXT(DATE(YEAR(H1), MONTH(H1)+1, DAY(H1)), "Mmm-yy") -> Jun-20 | J1: =TEXT(DATE(YEAR(I1), MONTH(I1)+1, DAY(I1)), "Mmm-yy") -> Jul-20 | K1: =TEXT(DATE(YEAR(J1), MONTH(J1)+1, DAY(J1)), "Mmm-yy") -> Aug-20 | L1: =TEXT(DATE(YEAR(K1), MONTH(K1)+1, DAY(K1)), "Mmm-yy") -> Sep-20 | ... EE1: =TEXT(DATE(YEAR(ED1), MONTH(ED1)+1, DAY(ED1)), "Mmm-yy") -> Dec-30
C2: KPI 1 | D2: =RANDBETWEEN(1, 100) -> 28 | E2: =RANDBETWEEN(1, 100) -> 35 | F2: =RANDBETWEEN(1, 100) -> 84 | G2: =RANDBETWEEN(1, 100) -> 86 | H2: =RANDBETWEEN(1, 100) -> 70 | I2: =RANDBETWEEN(1, 100) -> 73 | J2: =RANDBETWEEN(1, 100) -> 89 | K2: =RANDBETWEEN(1, 100) -> 24 | ... EE2: =RANDBETWEEN(1, 100) -> 37
A3: Copyright: Veera Seaman | C3: KPI 2 R | D3: =RAND() -> 0.58972396 | E3: =RAND() -> 0.35481936 | F3: =RAND() -> 0.71469038 | G3: =RAND() -> 0.05939163 | H3: =RAND() -> 0.67340492 | I3: =RAND() -> 0.6984097 | J3: =RAND() -> 0.54810923 | K3: =RAND() -> 0.57578581 | ... EE3: =RAND() -> 0.59967576
C4: KPI 3 | D4: =RAND() -> 0.81489311 | E4: =RAND() -> 0.27868891 | F4: =RAND() -> 0.28820648 | G4: =RAND() -> 0.7771392 | H4: =RAND() -> 0.64131214 | I4: =RAND() -> 0.12475151 | J4: =RAND() -> 0.61596739 | K4: =RAND() -> 0.72259576 | ... EE4: =RAND() -> 0.62470176
C5: KPI 4 % | D5: =RAND() -> 0.87307689 | E5: =RAND() -> 0.0044432596 | F5: =RAND() -> 0.19205503 | G5: =RAND() -> 0.65828092 | H5: =RAND() -> 0.690734 | I5: =RAND() -> 0.4676333 | J5: =RAND() -> 0.77774174 | K5: =RAND() -> 0.56106354 | ... EE5: =RAND() -> 0.26925921
C6: KPI 5 | D6: =RAND() -> 0.84971893 | E6: =RAND() -> 0.10890807 | F6: =RAND() -> 0.043052354 | G6: =RAND() -> 0.45820434 | H6: =RAND() -> 0.047518452 | I6: =RAND() -> 0.53409878 | J6: =RAND() -> 0.50202302 | K6: =RAND() -> 0.59250979 | ... EE6: =RAND() -> 0.54710227
C7: KPI 6 | D7: =RAND() -> 0.37870837 | E7: =RAND() -> 0.714618 | F7: =RAND() -> 0.14924998 | G7: =RAND() -> 0.93511987 | H7: =RAND() -> 0.23627896 | I7: =RAND() -> 0.41594627 | J7: =RAND() -> 0.47452739 | K7: =RAND() -> 0.73148674 | ... EE7: =RAND() -> 0.041778524
C8: KPI 7 | D8: =RAND() -> 0.098236466 | E8: =RAND() -> 0.031582855 | F8: =RAND() -> 0.19666513 | G8: =RAND() -> 0.94177999 | H8: =RAND() -> 0.97643525 | I8: =RAND() -> 0.59902499 | J8: =RAND() -> 0.68086843 | K8: =RAND() -> 0.32570354 | ... EE8: =RAND() -> 0.83705985
C9: KPI 8 % | D9: =RAND() -> 0.78926549 | E9: =RAND() -> 0.047841142 | F9: =RAND() -> 0.7985436 | G9: =RAND() -> 0.093536781 | H9: =RAND() -> 0.7532286 | I9: =RAND() -> 0.87268571 | J9: =RAND() -> 0.32885868 | K9: =RAND() -> 0.17842265 | ... EE9: =RAND() -> 0.66199694
C10: KPI 9 % | D10: =RAND() -> 0.4543267 | E10: =RAND() -> 0.77478423 | F10: =RAND() -> 0.98105038 | G10: =RAND() -> 0.22909457 | H10: =RAND() -> 0.58598511 | I10: =RAND() -> 0.047664702 | J10: =RAND() -> 0.32108979 | K10: =RAND() -> 0.62709148 | ... EE10: =RAND() -> 0.61823875
C11: KPI 10 | D11: =RANDBETWEEN(1, 100) -> 19 | E11: =RANDBETWEEN(1, 100) -> 37 | F11: =RANDBETWEEN(1, 100) -> 86 | G11: =RANDBETWEEN(1, 100) -> 55 | H11: =RANDBETWEEN(1, 100) -> 64 | I11: =RANDBETWEEN(1, 100) -> 75 | J11: =RANDBETWEEN(1, 100) -> 46 | K11: =RANDBETWEEN(1, 100) -> 15 | ... EE11: =RANDBETWEEN(1, 100) -> 88
C12: KPI 11 | D12: =RANDBETWEEN(20, 45) -> 26 | E12: =RANDBETWEEN(20, 45) -> 39 | F12: =RANDBETWEEN(20, 45) -> 35 | G12: =RANDBETWEEN(20, 45) -> 30 | H12: =RANDBETWEEN(20, 45) -> 41 | I12: =RANDBETWEEN(20, 45) -> 22 | J12: =RANDBETWEEN(20, 45) -> 34 | K12: =RANDBETWEEN(20, 45) -> 37 | ... EE12: =RANDBETWEEN(20, 45) -> 29
C13: KPI 12 % | D13: =RAND()+1 -> 1.5996849 | E13: =RAND()+1 -> 1.6051082 | F13: =RAND()+1 -> 1.0043407 | G13: =RAND()+1 -> 1.9215419 | H13: =RAND()+1 -> 1.4136963 | I13: =RAND()+1 -> 1.0230984 | J13: =RAND()+1 -> 1.8661333 | K13: =RAND()+1 -> 1.3611058 | ... EE13: =RAND()+1 -> 1.3834914
C14: KPI 13 | D14: =RANDBETWEEN(6, 10)+1.245 -> 9.245 | E14: =RANDBETWEEN(6, 10)+1.245 -> 8.245 | F14: =RANDBETWEEN(6, 10)+1.245 -> 8.245 | G14: =RANDBETWEEN(6, 10)+1.245 -> 10.245 | H14: =RANDBETWEEN(6, 10)+1.245 -> 7.245 | I14: =RANDBETWEEN(6, 10)+1.245 -> 10.245 | J14: =RANDBETWEEN(6, 10)+1.245 -> 11.245 | K14: =RANDBETWEEN(6, 10)+1.245 -> 10.245 | ... EE14: =RANDBETWEEN(6, 10)+1.245 -> 10.245
C15: KPI 14 | D15: =RANDBETWEEN(300, 440)+1.245 -> 310.245 | E15: =RANDBETWEEN(300, 440)+1.245 -> 351.245 | F15: =RANDBETWEEN(300, 440)+1.245 -> 344.245 | G15: =RANDBETWEEN(300, 440)+1.245 -> 399.245 | H15: =RANDBETWEEN(300, 440)+1.245 -> 399.245 | I15: =RANDBETWEEN(300, 440)+1.245 -> 351.245 | J15: =RANDBETWEEN(300, 440)+1.245 -> 433.245 | K15: =RANDBETWEEN(300, 440)+1.245 -> 379.245 | ... EE15: =RANDBETWEEN(300, 440)+1.245 -> 390.245
C16: KPI 15 | D16: =RAND() -> 0.90324376 | E16: =RAND() -> 0.19481463 | F16: =RAND() -> 0.21759848 | G16: =RAND() -> 0.85511298 | H16: =RAND() -> 0.72289411 | I16: =RAND() -> 0.58192364 | J16: =RAND() -> 0.24775124 | K16: =RAND() -> 0.10112986 | ... EE16: =RAND() -> 0.41715597
C17: KPI 16 % | D17: =RAND() -> 0.90277543 | E17: =RAND() -> 0.39954391 | F17: =RAND() -> 0.17192461 | G17: =RAND() -> 0.13100416 | H17: =RAND() -> 0.91626411 | I17: =RAND() -> 0.81447929 | J17: =RAND() -> 0.98254581 | K17: =RAND() -> 0.55387371 | ... EE17: =RAND() -> 0.61580781
C18: KPI 17 | D18: =RANDBETWEEN(1, 100) -> 81 | E18: =RANDBETWEEN(1, 100) -> 49 | F18: =RANDBETWEEN(1, 100) -> 88 | G18: =RANDBETWEEN(1, 100) -> 92 | H18: =RANDBETWEEN(1, 100) -> 91 | I18: =RANDBETWEEN(1, 100) -> 79 | J18: =RANDBETWEEN(1, 100) -> 23 | K18: =RANDBETWEEN(1, 100) -> 68 | ... EE18: =RANDBETWEEN(1, 100) -> 37
C19: KPI 18 | D19: =RANDBETWEEN(1, 200) -> 55 | E19: =RANDBETWEEN(1, 200) -> 186 | F19: =RANDBETWEEN(1, 200) -> 130 | G19: =RANDBETWEEN(1, 200) -> 6 | H19: =RANDBETWEEN(1, 200) -> 39 | I19: =RANDBETWEEN(1, 200) -> 36 | J19: =RANDBETWEEN(1, 200) -> 57 | K19: =RANDBETWEEN(1, 200) -> 113 | ... EE19: =RANDBETWEEN(1, 200) -> 8
C20: KPI 19 % | D20: =RANDBETWEEN(20, 45) -> 38 | E20: =RANDBETWEEN(20, 45) -> 29 | F20: =RANDBETWEEN(20, 45) -> 37 | G20: =RANDBETWEEN(20, 45) -> 40 | H20: =RANDBETWEEN(20, 45) -> 42 | I20: =RANDBETWEEN(20, 45) -> 21 | J20: =RANDBETWEEN(20, 45) -> 20 | K20: =RANDBETWEEN(20, 45) -> 29 | ... DQ20: =RANDBETWEEN(20, 45) -> 38 | DR20: =RAND()+1 -> 1.7855644 | DS20: =RANDBETWEEN(20, 45) -> 21 | DT20: =RANDBETWEEN(20, 45) -> 30 | DU20: =RANDBETWEEN(20, 45) -> 40 | DV20: =RANDBETWEEN(20, 45) -> 37 | DW20: =RANDBETWEEN(20, 45) -> 21 | DX20: =RANDBETWEEN(20, 45) -> 36 | DY20: =RANDBETWEEN(20, 45) -> 23 | DZ20: =RANDBETWEEN(20, 45) -> 22 | ... EE20: =RANDBETWEEN(20, 45) -> 42
C21: KPI 20 % | D21: =RAND()*0.224 -> 0.16279608 | E21: =RAND()*0.224 -> 0.10303152 | F21: =RAND()*0.224 -> 0.045646005 | G21: =RAND()*0.224 -> 0.16775129 | H21: =RAND()*0.224 -> 0.043235561 | I21: =RAND()*0.224 -> 0.22289525 | J21: =RAND()*0.224 -> 0.14141817 | K21: =RAND()*0.224 -> 0.059202064 | ... EE21: =RAND()*0.224 -> 0.0093585425
C22: KPI 21 % | D22: =RAND() -> 0.40773065 | E22: =RAND() -> 0.31573186 | F22: =RAND() -> 0.37967875 | G22: =RAND() -> 0.73025962 | H22: =RAND() -> 0.39623717 | I22: =RAND() -> 0.86594208 | J22: =RAND() -> 0.60664628 | K22: =RAND() -> 0.15712761 | ... EE22: =RAND() -> 0.71738418
C23: KPI 22 | D23: =RAND()+1 -> 1.5588197 | E23: =RAND()+1 -> 1.2649519 | F23: =RAND()+1 -> 1.3275393 | G23: =RAND()+1 -> 1.1713969 | H23: =RAND()+1 -> 1.5681414 | I23: =RAND()+1 -> 1.7173387 | J23: =RAND()+1 -> 1.4094807 | K23: =RAND()+1 -> 1.8802507 | ... DP23: =RAND()+1 -> 1.3017812 | DQ23: =RANDBETWEEN(20, 45) -> 20 | DR23: =RAND()+1 -> 1.3498592 | DS23: =RAND()+1 -> 1.395878 | DT23: =RAND()+1 -> 1.6270497 | DU23: =RAND()+1 -> 1.7329029 | DV23: =RAND()+1 -> 1.2755013 | DW23: =RAND()+1 -> 1.7009973 | DX23: =RAND()+1 -> 1.0511966 | DY23: =RAND()+1 -> 1.8355155 | ... EE23: =RAND()+1 -> 1.0270266
C24: KPI 23 R | D24: =RANDBETWEEN(1, 200) -> 38 | E24: =RANDBETWEEN(1, 200) -> 163 | F24: =RANDBETWEEN(1, 200) -> 60 | G24: =RANDBETWEEN(1, 200) -> 105 | H24: =RANDBETWEEN(1, 200) -> 34 | I24: =RANDBETWEEN(1, 200) -> 8 | J24: =RANDBETWEEN(1, 200) -> 10 | K24: =RANDBETWEEN(1, 200) -> 104 | ... EE24: =RANDBETWEEN(1, 200) -> 11
C25: KPI 24 | D25: =RANDBETWEEN(20, 45) -> 35 | E25: =RANDBETWEEN(20, 45) -> 26 | F25: =RANDBETWEEN(20, 45) -> 36 | G25: =RANDBETWEEN(20, 45) -> 27 | H25: =RANDBETWEEN(20, 45) -> 22 | I25: =RANDBETWEEN(20, 45) -> 33 | J25: =RANDBETWEEN(20, 45) -> 26 | K25: =RANDBETWEEN(20, 45) -> 40 | ... DM25: =RANDBETWEEN(20, 45) -> 21 | DN25: =RAND()+1 -> 1.7775658 | DO25: =RANDBETWEEN(20, 45) -> 42 | DP25: =RANDBETWEEN(20, 45) -> 24 | DQ25: =RANDBETWEEN(20, 45) -> 27 | DR25: =RANDBETWEEN(20, 45) -> 45 | DS25: =RANDBETWEEN(20, 45) -> 27 | DT25: =RANDBETWEEN(20, 45) -> 27 | DU25: =RANDBETWEEN(20, 45) -> 41 | DV25: =RANDBETWEEN(20, 45) -> 30 | ... ED25: =RANDBETWEEN(20, 45) -> 45 | EE25: =RAND() -> 0.62572021
C26: KPI 25 R | D26: =RANDBETWEEN(1, 33) -> 2 | E26: =RANDBETWEEN(1, 33) -> 1 | F26: =RANDBETWEEN(1, 33) -> 12 | G26: =RANDBETWEEN(1, 33) -> 32 | H26: =RANDBETWEEN(1, 33) -> 8 | I26: =RANDBETWEEN(1, 33) -> 20 | J26: =RANDBETWEEN(1, 33) -> 10 | K26: =RANDBETWEEN(1, 33) -> 31 | ... EE26: =RANDBETWEEN(1, 33) -> 16
C27: KPI 26 | D27: =RANDBETWEEN(0, 45) -> 20 | E27: =RANDBETWEEN(0, 45) -> 38 | F27: =RANDBETWEEN(0, 45) -> 12 | G27: =RANDBETWEEN(0, 45) -> 3 | H27: =RANDBETWEEN(0, 45) -> 20 | I27: =RANDBETWEEN(0, 45) -> 10 | J27: =RANDBETWEEN(0, 45) -> 10 | K27: =RANDBETWEEN(0, 45) -> 24 | ... EE27: =RANDBETWEEN(0, 45) -> 32
C28: KPI 27 | D28: =RAND() -> 0.71227515 | E28: =RAND() -> 0.6771815 | F28: =RAND() -> 0.36902394 | G28: =RAND() -> 0.083717515 | H28: =RAND() -> 0.027646832 | I28: =RAND() -> 0.20480999 | J28: =RAND() -> 0.15161895 | K28: =RAND() -> 0.48193927 | ... EE28: =RAND() -> 0.15147206
C29: KPI 28 % | D29: =RAND()+1 -> 1.9084433 | E29: =RAND()+1 -> 1.8350193 | F29: =RAND()+1 -> 1.4723757 | G29: =RAND()+1 -> 1.3158845 | H29: =RAND()+1 -> 1.1592443 | I29: =RAND()+1 -> 1.9346178 | J29: =RAND()+1 -> 1.8644845 | K29: =RAND()+1 -> 1.1295519 | ... EE29: =RAND()+1 -> 1.8029089
C30: KPI 29 % | D30: =RANDBETWEEN(20, 45) -> 28 | E30: =RANDBETWEEN(20, 45) -> 24 | F30: =RANDBETWEEN(20, 45) -> 31 | G30: =RANDBETWEEN(20, 45) -> 45 | H30: =RANDBETWEEN(20, 45) -> 25 | I30: =RANDBETWEEN(20, 45) -> 42 | J30: =RANDBETWEEN(20, 45) -> 43 | K30: =RANDBETWEEN(20, 45) -> 23 | ... EE30: =RANDBETWEEN(20, 45) -> 45
C31: KPI 30 | D31: =RANDBETWEEN(20, 45) -> 24 | E31: =RANDBETWEEN(20, 45) -> 29 | F31: =RANDBETWEEN(20, 45) -> 40 | G31: =RANDBETWEEN(20, 45) -> 40 | H31: =RANDBETWEEN(20, 45) -> 28 | I31: =RANDBETWEEN(20, 45) -> 37 | J31: =RANDBETWEEN(20, 45) -> 35 | K31: =RANDBETWEEN(20, 45) -> 32 | ... DN31: =RANDBETWEEN(20, 45) -> 34 | DO31: =RAND()+1 -> 1.8454015 | DP31: =RANDBETWEEN(20, 45) -> 22 | DQ31: =RANDBETWEEN(20, 45) -> 45 | DR31: =RANDBETWEEN(20, 45) -> 42 | DS31: =RANDBETWEEN(20, 45) -> 27 | DT31: =RANDBETWEEN(20, 45) -> 45 | DU31: =RANDBETWEEN(20, 45) -> 41 | DV31: =RANDBETWEEN(20, 45) -> 31 | DW31: =RANDBETWEEN(20, 45) -> 43 | ... ED31: =RANDBETWEEN(20, 45) -> 30 | EE31: =RAND() -> 0.30418608
C32: KPI 31 R | D32: =RANDBETWEEN(20, 45) -> 42 | E32: =RANDBETWEEN(20, 45) -> 26 | F32: =RANDBETWEEN(20, 45) -> 21 | G32: =RANDBETWEEN(20, 45) -> 30 | H32: =RANDBETWEEN(20, 45) -> 27 | I32: =RANDBETWEEN(20, 45) -> 34 | J32: =RANDBETWEEN(20, 45) -> 30 | K32: =RANDBETWEEN(20, 45) -> 26 | ... EE32: =RANDBETWEEN(20, 45) -> 32
C33: KPI 32 | D33: {=_xlfn.RANDARRAY()} -> 0.7248324 | E33: {=_xlfn.RANDARRAY()} -> 0.89528087 | F33: {=_xlfn.RANDARRAY()} -> 0.75325042 | G33: {=_xlfn.RANDARRAY()} -> 0.019951888 | H33: {=_xlfn.RANDARRAY()} -> 0.068334072 | I33: {=_xlfn.RANDARRAY()} -> 0.20283687 | J33: {=_xlfn.RANDARRAY()} -> 0.13501957 | K33: {=_xlfn.RANDARRAY()} -> 0.35516864 | ... DN33: {=_xlfn.RANDARRAY()} -> 0.43075172 | DO33: =RANDBETWEEN(20, 45) -> 41 | DP33: {=_xlfn.RANDARRAY()} -> 0.31812982 | DQ33: {=_xlfn.RANDARRAY()} -> 0.67597855 | DR33: {=_xlfn.RANDARRAY()} -> 0.89632523 | DS33: {=_xlfn.RANDARRAY()} -> 0.94080252 | DT33: {=_xlfn.RANDARRAY()} -> 0.62175159 | DU33: {=_xlfn.RANDARRAY()} -> 0.95329374 | DV33: {=_xlfn.RANDARRAY()} -> 0.37428392 | DW33: {=_xlfn.RANDARRAY()} -> 0.4228802 | ... EE33: {=_xlfn.RANDARRAY()} -> 0.96190017
B35: Displaying data:
C36: Month and year | D36: =TEXT(D1, "Mmm-YY") -> Jan-20 | E36: =TEXT(E1, "Mmm-YY") -> Feb-20 | F36: =TEXT(F1, "Mmm-YY") -> Mar-20 | G36: =TEXT(G1, "Mmm-YY") -> Apr-20 | H36: =TEXT(H1, "Mmm-YY") -> May-20 | I36: =TEXT(I1, "Mmm-YY") -> Jun-20 | J36: =TEXT(J1, "Mmm-YY") -> Jul-20 | K36: =TEXT(K1, "Mmm-YY") -> Aug-20 | ... EE36: =TEXT(EE1, "Mmm-YY") -> Dec-30
B37: Select KPI: | C37: KPI 9 % | D37: =(IFERROR(INDEX(Raw!$C$1:$EE$33,MATCH($C37,Raw!$C$1:$C$33,0),MATCH(D$36,Raw!$C$1:$EE$1,0)),"-")) -> 0.4543267 | E37: =(IFERROR(INDEX(Raw!$C$1:$EE$33,MATCH($C37,Raw!$C$1:$C$33,0),MATCH(E$36,Raw!$C$1:$EE$1,0)),"-")) -> 0.77478423 | F37: =(IFERROR(INDEX(Raw!$C$1:$EE$33,MATCH($C37,Raw!$C$1:$C$33,0),MATCH(F$36,Raw!$C$1:$EE$1,0)),"-")) -> 0.98105038 | G37: =(IFERROR(INDEX(Raw!$C$1:$EE$33,MATCH($C37,Raw!$C$1:$C$33,0),MATCH(G$36,Raw!$C$1:$EE$1,0)),"-")) -> 0.22909457 | H37: =(IFERROR(INDEX(Raw!$C$1:$EE$33,MATCH($C37,Raw!$C$1:$C$33,0),MATCH(H$36,Raw!$C$1:$EE$1,0)),"-")) -> 0.58598511 | I37: =(IFERROR(INDEX(Raw!$C$1:$EE$33,MATCH($C37,Raw!$C$1:$C$33,0),MATCH(I$36,Raw!$C$1:$EE$1,0)),"-")) -> 0.047664702 | J37: =(IFERROR(INDEX(Raw!$C$1:$EE$33,MATCH($C37,Raw!$C$1:$C$33,0),MATCH(J$36,Raw!$C$1:$EE$1,0)),"-")) -> 0.32108979 | K37: =(IFERROR(INDEX(Raw!$C$1:$EE$33,MATCH($C37,Raw!$C$1:$C$33,0),MATCH(K$36,Raw!$C$1:$EE$1,0)),"-")) -> 0.62709148 | ... EE37: =(IFERROR(INDEX(Raw!$C$1:$EE$33,MATCH($C37,Raw!$C$1:$C$33,0),MATCH(EE$36,Raw!$C$1:$EE$1,0)),"-")) -> 0.61823875
B38: Select KPI: | C38: KPI 9 % | D38: =(IFERROR(INDEX(Raw!$C$1:$EE$33,MATCH($C38,Raw!$C$1:$C$33,0),MATCH(D$36,Raw!$C$1:$EE$1,0)),"-")) -> 0.4543267 | E38: =(IFERROR(INDEX(Raw!$C$1:$EE$33,MATCH($C38,Raw!$C$1:$C$33,0),MATCH(E$36,Raw!$C$1:$EE$1,0)),"-")) -> 0.77478423 | F38: =(IFERROR(INDEX(Raw!$C$1:$EE$33,MATCH($C38,Raw!$C$1:$C$33,0),MATCH(F$36,Raw!$C$1:$EE$1,0)),"-")) -> 0.98105038 | G38: =(IFERROR(INDEX(Raw!$C$1:$EE$33,MATCH($C38,Raw!$C$1:$C$33,0),MATCH(G$36,Raw!$C$1:$EE$1,0)),"-")) -> 0.22909457 | H38: =(IFERROR(INDEX(Raw!$C$1:$EE$33,MATCH($C38,Raw!$C$1:$C$33,0),MATCH(H$36,Raw!$C$1:$EE$1,0)),"-")) -> 0.58598511 | I38: =(IFERROR(INDEX(Raw!$C$1:$EE$33,MATCH($C38,Raw!$C$1:$C$33,0),MATCH(I$36,Raw!$C$1:$EE$1,0)),"-")) -> 0.047664702 | J38: =(IFERROR(INDEX(Raw!$C$1:$EE$33,MATCH($C38,Raw!$C$1:$C$33,0),MATCH(J$36,Raw!$C$1:$EE$1,0)),"-")) -> 0.32108979 | K38: =(IFERROR(INDEX(Raw!$C$1:$EE$33,MATCH($C38,Raw!$C$1:$C$33,0),MATCH(K$36,Raw!$C$1:$EE$1,0)),"-")) -> 0.62709148 | ... EE38: =(IFERROR(INDEX(Raw!$C$1:$EE$33,MATCH($C38,Raw!$C$1:$C$33,0),MATCH(EE$36,Raw!$C$1:$EE$1,0)),"-")) -> 0.61823875
B39: Select KPI: | C39: KPI 9 % | D39: =(IFERROR(INDEX(Raw!$C$1:$EE$33,MATCH($C39,Raw!$C$1:$C$33,0),MATCH(D$36,Raw!$C$1:$EE$1,0)),"-")) -> 0.4543267 | E39: =(IFERROR(INDEX(Raw!$C$1:$EE$33,MATCH($C39,Raw!$C$1:$C$33,0),MATCH(E$36,Raw!$C$1:$EE$1,0)),"-")) -> 0.77478423 | F39: =(IFERROR(INDEX(Raw!$C$1:$EE$33,MATCH($C39,Raw!$C$1:$C$33,0),MATCH(F$36,Raw!$C$1:$EE$1,0)),"-")) -> 0.98105038 | G39: =(IFERROR(INDEX(Raw!$C$1:$EE$33,MATCH($C39,Raw!$C$1:$C$33,0),MATCH(G$36,Raw!$C$1:$EE$1,0)),"-")) -> 0.22909457 | H39: =(IFERROR(INDEX(Raw!$C$1:$EE$33,MATCH($C39,Raw!$C$1:$C$33,0),MATCH(H$36,Raw!$C$1:$EE$1,0)),"-")) -> 0.58598511 | I39: =(IFERROR(INDEX(Raw!$C$1:$EE$33,MATCH($C39,Raw!$C$1:$C$33,0),MATCH(I$36,Raw!$C$1:$EE$1,0)),"-")) -> 0.047664702 | J39: =(IFERROR(INDEX(Raw!$C$1:$EE$33,MATCH($C39,Raw!$C$1:$C$33,0),MATCH(J$36,Raw!$C$1:$EE$1,0)),"-")) -> 0.32108979 | K39: =(IFERROR(INDEX(Raw!$C$1:$EE$33,MATCH($C39,Raw!$C$1:$C$33,0),MATCH(K$36,Raw!$C$1:$EE$1,0)),"-")) -> 0.62709148 | ... EE39: =(IFERROR(INDEX(Raw!$C$1:$EE$33,MATCH($C39,Raw!$C$1:$C$33,0),MATCH(EE$36,Raw!$C$1:$EE$1,0)),"-")) -> 0.61823875
B40: Select KPI: | C40: KPI 10 | D40: =(IFERROR(INDEX(Raw!$C$1:$EE$33,MATCH($C40,Raw!$C$1:$C$33,0),MATCH(D$36,Raw!$C$1:$EE$1,0)),"-")) -> 19 | E40: =(IFERROR(INDEX(Raw!$C$1:$EE$33,MATCH($C40,Raw!$C$1:$C$33,0),MATCH(E$36,Raw!$C$1:$EE$1,0)),"-")) -> 37 | F40: =(IFERROR(INDEX(Raw!$C$1:$EE$33,MATCH($C40,Raw!$C$1:$C$33,0),MATCH(F$36,Raw!$C$1:$EE$1,0)),"-")) -> 86 | G40: =(IFERROR(INDEX(Raw!$C$1:$EE$33,MATCH($C40,Raw!$C$1:$C$33,0),MATCH(G$36,Raw!$C$1:$EE$1,0)),"-")) -> 55 | H40: =(IFERROR(INDEX(Raw!$C$1:$EE$33,MATCH($C40,Raw!$C$1:$C$33,0),MATCH(H$36,Raw!$C$1:$EE$1,0)),"-")) -> 64 | I40: =(IFERROR(INDEX(Raw!$C$1:$EE$33,MATCH($C40,Raw!$C$1:$C$33,0),MATCH(I$36,Raw!$C$1:$EE$1,0)),"-")) -> 75 | J40: =(IFERROR(INDEX(Raw!$C$1:$EE$33,MATCH($C40,Raw!$C$1:$C$33,0),MATCH(J$36,Raw!$C$1:$EE$1,0)),"-")) -> 46 | K40: =(IFERROR(INDEX(Raw!$C$1:$EE$33,MATCH($C40,Raw!$C$1:$C$33,0),MATCH(K$36,Raw!$C$1:$EE$1,0)),"-")) -> 15 | ... EE40: =(IFERROR(INDEX(Raw!$C$1:$EE$33,MATCH($C40,Raw!$C$1:$C$33,0),MATCH(EE$36,Raw!$C$1:$EE$1,0)),"-")) -> 88
B41: Select KPI: | C41: KPI 31 R | D41: =(IFERROR(INDEX(Raw!$C$1:$EE$33,MATCH($C41,Raw!$C$1:$C$33,0),MATCH(D$36,Raw!$C$1:$EE$1,0)),"-")) -> 42 | E41: =(IFERROR(INDEX(Raw!$C$1:$EE$33,MATCH($C41,Raw!$C$1:$C$33,0),MATCH(E$36,Raw!$C$1:$EE$1,0)),"-")) -> 26 | F41: =(IFERROR(INDEX(Raw!$C$1:$EE$33,MATCH($C41,Raw!$C$1:$C$33,0),MATCH(F$36,Raw!$C$1:$EE$1,0)),"-")) -> 21 | G41: =(IFERROR(INDEX(Raw!$C$1:$EE$33,MATCH($C41,Raw!$C$1:$C$33,0),MATCH(G$36,Raw!$C$1:$EE$1,0)),"-")) -> 30 | H41: =(IFERROR(INDEX(Raw!$C$1:$EE$33,MATCH($C41,Raw!$C$1:$C$33,0),MATCH(H$36,Raw!$C$1:$EE$1,0)),"-")) -> 27 | I41: =(IFERROR(INDEX(Raw!$C$1:$EE$33,MATCH($C41,Raw!$C$1:$C$33,0),MATCH(I$36,Raw!$C$1:$EE$1,0)),"-")) -> 34 | J41: =(IFERROR(INDEX(Raw!$C$1:$EE$33,MATCH($C41,Raw!$C$1:$C$33,0),MATCH(J$36,Raw!$C$1:$EE$1,0)),"-")) -> 30 | K41: =(IFERROR(INDEX(Raw!$C$1:$EE$33,MATCH($C41,Raw!$C$1:$C$33,0),MATCH(K$36,Raw!$C$1:$EE$1,0)),"-")) -> 26 | ... EE41: =(IFERROR(INDEX(Raw!$C$1:$EE$33,MATCH($C41,Raw!$C$1:$C$33,0),MATCH(EE$36,Raw!$C$1:$EE$1,0)),"-")) -> 32
...
