Workbook
Name Colours: Aloitus!$D$2:$G$2

Sheet Aloitus
B2: Valitse teema: | C2: Kevät | D2: Otsikko | E2: Korostus | G2: Copyright
B4: Lisää yrityksen logo (logon tulee mahtua merkityn alueen sisään):
B5: Poista Your logo-kuva ja lisää omasi:
B8: Värivaihtoehtoja voidaan lisätä toiveidesi mukaan.

Sheet Listat
C2: =Aloitus!$C$2 -> Kevät
C7: =TEXT(TODAY(), "Mmmm") -> October | D7: =TEXT(TODAY(), "Yyyy") -> 2025
C8: Vaihda vieressä olevaan oman datasi aloitusvuosi (ensimmäinen vuosi, josta datasi alkaa): | F8: 2025
B10: # | C10: Kuukausi | E10: Vuosi | F10: Vuosilaskelma (älä muokkaa näitä):
B11: 0 | C11: =TEXT(TODAY(), "Mmmm") -> October | E11: =F8 -> 2025 | F11: =E11-$D$7 -> 0
B12: 1 | C12: =TEXT(DATE(YEAR(TODAY()),MONTH(TODAY())+B12,DAY(TODAY())), "Mmmm") -> November | E12: =E11+1 -> 2026 | F12: =E12-$D$7 -> 1
B13: 2 | C13: =TEXT(DATE(YEAR(TODAY()),MONTH(TODAY())+B13,DAY(TODAY())), "Mmmm") -> December | E13: =E12+1 -> 2027 | F13: =E13-$D$7 -> 2
B14: 3 | C14: =TEXT(DATE(YEAR(TODAY()),MONTH(TODAY())+B14,DAY(TODAY())), "Mmmm") -> January | E14: =E13+1 -> 2028 | F14: =E14-$D$7 -> 3
B15: 4 | C15: =TEXT(DATE(YEAR(TODAY()),MONTH(TODAY())+B15,DAY(TODAY())), "Mmmm") -> March | E15: =E14+1 -> 2029 | F15: =E15-$D$7 -> 4
B16: 5 | C16: =TEXT(DATE(YEAR(TODAY()),MONTH(TODAY())+B16,DAY(TODAY())), "Mmmm") -> March | E16: =E15+1 -> 2030 | F16: =E16-$D$7 -> 5
B17: 6 | C17: =TEXT(DATE(YEAR(TODAY()),MONTH(TODAY())+B17,DAY(TODAY())), "Mmmm") -> April | E17: =E16+1 -> 2031 | F17: =E17-$D$7 -> 6
B18: 7 | C18: =TEXT(DATE(YEAR(TODAY()),MONTH(TODAY())+B18,DAY(TODAY())), "Mmmm") -> May | E18: =E17+1 -> 2032 | F18: =E18-$D$7 -> 7
B19: 8 | C19: =TEXT(DATE(YEAR(TODAY()),MONTH(TODAY())+B19,DAY(TODAY())), "Mmmm") -> June | E19: =E18+1 -> 2033 | F19: =E19-$D$7 -> 8
B20: 9 | C20: =TEXT(DATE(YEAR(TODAY()),MONTH(TODAY())+B20,DAY(TODAY())), "Mmmm") -> July | E20: =E19+1 -> 2034 | F20: =E20-$D$7 -> 9
B21: 10 | C21: =TEXT(DATE(YEAR(TODAY()),MONTH(TODAY())+B21,DAY(TODAY())), "Mmmm") -> August | E21: =E20+1 -> 2035 | F21: =E21-$D$7 -> 10
B22: 11 | C22: =TEXT(DATE(YEAR(TODAY()),MONTH(TODAY())+B22,DAY(TODAY())), "Mmmm") -> September | E22: =E21+1 -> 2036 | F22: =E22-$D$7 -> 11
E23: =E22+1 -> 2037 | F23: =E23-$D$7 -> 12
E24: =E23+1 -> 2038 | F24: =E24-$D$7 -> 13
E25: =E24+1 -> 2039 | F25: =E25-$D$7 -> 14
E26: =E25+1 -> 2040 | F26: =E26-$D$7 -> 15

Sheet Dashboard
C2: =Aloitus!$C$2 -> Kevät
D6: =TEXT(($C$7&" "&$C$8),"MMm-YY") -> Jun-26
B7: Valitse kuukausi: | C7: June
B8: Valitse vuosi: | C8: 2026
B10: =VLOOKUP(B13, Data!$A$8:$B$200, 2, FALSE) -> Virheellisten tuotteiden määrä koko inventaariosta (%)
B12: Month and year | C12: =IF(ISBLANK($D$6),"",(TEXT(($D$6),"mmm-yy"))) -> Jun-26 | D12: =(TEXT(DATE(YEAR(C12),MONTH(C12)+1,DAY(C12)),"MMM-YY")) -> Jul-26 | E12: =(TEXT(DATE(YEAR(D12),MONTH(D12)+1,DAY(D12)),"MMM-YY")) -> Aug-26 | F12: =(TEXT(DATE(YEAR(E12),MONTH(E12)+1,DAY(E12)),"MMM-YY")) -> Sep-26 | G12: =(TEXT(DATE(YEAR(F12),MONTH(F12)+1,DAY(F12)),"MMM-YY")) -> Oct-26 | H12: =(TEXT(DATE(YEAR(G12),MONTH(G12)+1,DAY(G12)),"MMM-YY")) -> Nov-26 | I12: =(TEXT(DATE(YEAR(H12),MONTH(H12)+1,DAY(H12)),"MMM-YY")) -> Dec-26 | J12: =(TEXT(DATE(YEAR(I12),MONTH(I12)+1,DAY(I12)),"MMM-YY")) -> Jan-27 | K12: =(TEXT(DATE(YEAR(J12),MONTH(J12)+1,DAY(J12)),"MMM-YY")) -> Feb-27 | ... M12: =(TEXT(DATE(YEAR(L12),MONTH(L12)+1,DAY(L12)),"MMM-YY")) -> Apr-27 | P12: =IFERROR(IF(DATEVALUE(M12)>=DATEVALUE($EF$5),"",(TEXT(DATE(YEAR(M12),MONTH(M12)+1,DAY(M12)),"MMM-YY"))),"") | Q12: =IFERROR(IF(DATEVALUE(P12)>=DATEVALUE($EF$5),"",(TEXT(DATE(YEAR(P12),MONTH(P12)+1,DAY(P12)),"MMM-YY"))),"")
B13: KPI ID 8 % | C13: =IF(ISBLANK($D$6),"",(IFERROR(INDEX(Data!$C$7:$EE$39,MATCH($B13,Data!$C$7:$C$39,0),MATCH(C12,Data!$C$7:$EE$7,0)),""))) -> 0.9816943 | D13: =IF(ISBLANK($D$6),"",(IFERROR(INDEX(Data!$C$7:$EE$39,MATCH($B13,Data!$C$7:$C$39,0),MATCH(D12,Data!$C$7:$EE$7,0)),""))) -> 0.53794862 | E13: =IF(ISBLANK($D$6),"",(IFERROR(INDEX(Data!$C$7:$EE$39,MATCH($B13,Data!$C$7:$C$39,0),MATCH(E12,Data!$C$7:$EE$7,0)),""))) -> 0.49586536 | F13: =IF(ISBLANK($D$6),"",(IFERROR(INDEX(Data!$C$7:$EE$39,MATCH($B13,Data!$C$7:$C$39,0),MATCH(F12,Data!$C$7:$EE$7,0)),""))) -> 0.40024291 | G13: =IF(ISBLANK($D$6),"",(IFERROR(INDEX(Data!$C$7:$EE$39,MATCH($B13,Data!$C$7:$C$39,0),MATCH(G12,Data!$C$7:$EE$7,0)),""))) -> 0.53262063 | H13: =IF(ISBLANK($D$6),"",(IFERROR(INDEX(Data!$C$7:$EE$39,MATCH($B13,Data!$C$7:$C$39,0),MATCH(H12,Data!$C$7:$EE$7,0)),""))) -> 0.11344027 | I13: =IF(ISBLANK($D$6),"",(IFERROR(INDEX(Data!$C$7:$EE$39,MATCH($B13,Data!$C$7:$C$39,0),MATCH(I12,Data!$C$7:$EE$7,0)),""))) -> 0.012497982 | J13: =IF(ISBLANK($D$6),"",(IFERROR(INDEX(Data!$C$7:$EE$39,MATCH($B13,Data!$C$7:$C$39,0),MATCH(J12,Data!$C$7:$EE$7,0)),""))) -> 0.026418797 | ... M13: =IF(ISBLANK($D$6),"",(IFERROR(INDEX(Data!$C$7:$EE$39,MATCH($B13,Data!$C$7:$C$39,0),MATCH(M12,Data!$C$7:$EE$7,0)),""))) -> 0.37693467 | P13: =(IFERROR(INDEX(Data!$C$7:$EE$39,MATCH(#REF!,Data!$C$7:$C$39,0),MATCH(P$87,Data!$C$7:$EE$7,0)),"")) | Q13: =(IFERROR(INDEX(Data!$C$7:$EE$39,MATCH(#REF!,Data!$C$7:$C$39,0),MATCH(Q$87,Data!$C$7:$EE$7,0)),""))
B30: =VLOOKUP(B33, Data!$A$8:$B$200, 2, FALSE) -> Punaisten rantapyyhkeiden määrä varastossa
B32: Month and year | C32: =IF(ISBLANK($D$6),"",(TEXT(($D$6),"mmm-yy"))) -> Jun-26 | D32: =(TEXT(DATE(YEAR(C32),MONTH(C32)+1,DAY(C32)),"MMM-YY")) -> Jul-26 | E32: =(TEXT(DATE(YEAR(D32),MONTH(D32)+1,DAY(D32)),"MMM-YY")) -> Aug-26 | F32: =(TEXT(DATE(YEAR(E32),MONTH(E32)+1,DAY(E32)),"MMM-YY")) -> Sep-26 | G32: =(TEXT(DATE(YEAR(F32),MONTH(F32)+1,DAY(F32)),"MMM-YY")) -> Oct-26 | H32: =(TEXT(DATE(YEAR(G32),MONTH(G32)+1,DAY(G32)),"MMM-YY")) -> Nov-26 | I32: =(TEXT(DATE(YEAR(H32),MONTH(H32)+1,DAY(H32)),"MMM-YY")) -> Dec-26 | J32: =(TEXT(DATE(YEAR(I32),MONTH(I32)+1,DAY(I32)),"MMM-YY")) -> Jan-27 | K32: =(TEXT(DATE(YEAR(J32),MONTH(J32)+1,DAY(J32)),"MMM-YY")) -> Feb-27 | ... M32: =(TEXT(DATE(YEAR(L32),MONTH(L32)+1,DAY(L32)),"MMM-YY")) -> Apr-27 | P32: =IFERROR(IF(DATEVALUE(M32)>=DATEVALUE($EF$5),"",(TEXT(DATE(YEAR(M32),MONTH(M32)+1,DAY(M32)),"MMM-YY"))),"") | Q32: =IFERROR(IF(DATEVALUE(P32)>=DATEVALUE($EF$5),"",(TEXT(DATE(YEAR(P32),MONTH(P32)+1,DAY(P32)),"MMM-YY"))),"")
B33: KPI ID 6 | C33: =IF(ISBLANK($D$6),"",(IFERROR(INDEX(Data!$C$7:$EE$39,MATCH($B33,Data!$C$7:$C$39,0),MATCH(C32,Data!$C$7:$EE$7,0)),""))) -> 35 | D33: =IF(ISBLANK($D$6),"",(IFERROR(INDEX(Data!$C$7:$EE$39,MATCH($B33,Data!$C$7:$C$39,0),MATCH(D32,Data!$C$7:$EE$7,0)),""))) -> 9 | E33: =IF(ISBLANK($D$6),"",(IFERROR(INDEX(Data!$C$7:$EE$39,MATCH($B33,Data!$C$7:$C$39,0),MATCH(E32,Data!$C$7:$EE$7,0)),""))) -> 7 | F33: =IF(ISBLANK($D$6),"",(IFERROR(INDEX(Data!$C$7:$EE$39,MATCH($B33,Data!$C$7:$C$39,0),MATCH(F32,Data!$C$7:$EE$7,0)),""))) -> 8 | G33: =IF(ISBLANK($D$6),"",(IFERROR(INDEX(Data!$C$7:$EE$39,MATCH($B33,Data!$C$7:$C$39,0),MATCH(G32,Data!$C$7:$EE$7,0)),""))) -> 9 | H33: =IF(ISBLANK($D$6),"",(IFERROR(INDEX(Data!$C$7:$EE$39,MATCH($B33,Data!$C$7:$C$39,0),MATCH(H32,Data!$C$7:$EE$7,0)),""))) -> 37 | I33: =IF(ISBLANK($D$6),"",(IFERROR(INDEX(Data!$C$7:$EE$39,MATCH($B33,Data!$C$7:$C$39,0),MATCH(I32,Data!$C$7:$EE$7,0)),""))) -> 34 | J33: =IF(ISBLANK($D$6),"",(IFERROR(INDEX(Data!$C$7:$EE$39,MATCH($B33,Data!$C$7:$C$39,0),MATCH(J32,Data!$C$7:$EE$7,0)),""))) -> 20 | ... M33: =IF(ISBLANK($D$6),"",(IFERROR(INDEX(Data!$C$7:$EE$39,MATCH($B33,Data!$C$7:$C$39,0),MATCH(M32,Data!$C$7:$EE$7,0)),""))) -> 8 | P33: =(IFERROR(INDEX(Data!$C$7:$EE$39,MATCH(#REF!,Data!$C$7:$C$39,0),MATCH(P$87,Data!$C$7:$EE$7,0)),"")) | Q33: =(IFERROR(INDEX(Data!$C$7:$EE$39,MATCH(#REF!,Data!$C$7:$C$39,0),MATCH(Q$87,Data!$C$7:$EE$7,0)),""))
B50: =VLOOKUP(B53, Data!$A$8:$B$200, 2, FALSE) -> Esimerkki indikaattori
B52: Month and year | C52: =IF(ISBLANK($D$6),"",(TEXT(($D$6),"mmm-yy"))) -> Jun-26 | D52: =(TEXT(DATE(YEAR(C52),MONTH(C52)+1,DAY(C52)),"MMM-YY")) -> Jul-26 | E52: =(TEXT(DATE(YEAR(D52),MONTH(D52)+1,DAY(D52)),"MMM-YY")) -> Aug-26 | F52: =(TEXT(DATE(YEAR(E52),MONTH(E52)+1,DAY(E52)),"MMM-YY")) -> Sep-26 | G52: =(TEXT(DATE(YEAR(F52),MONTH(F52)+1,DAY(F52)),"MMM-YY")) -> Oct-26 | H52: =(TEXT(DATE(YEAR(G52),MONTH(G52)+1,DAY(G52)),"MMM-YY")) -> Nov-26 | I52: =(TEXT(DATE(YEAR(H52),MONTH(H52)+1,DAY(H52)),"MMM-YY")) -> Dec-26 | J52: =(TEXT(DATE(YEAR(I52),MONTH(I52)+1,DAY(I52)),"MMM-YY")) -> Jan-27 | K52: =(TEXT(DATE(YEAR(J52),MONTH(J52)+1,DAY(J52)),"MMM-YY")) -> Feb-27 | ... M52: =(TEXT(DATE(YEAR(L52),MONTH(L52)+1,DAY(L52)),"MMM-YY")) -> Apr-27 | P52: =IFERROR(IF(DATEVALUE(M52)>=DATEVALUE($EF$5),"",(TEXT(DATE(YEAR(M52),MONTH(M52)+1,DAY(M52)),"MMM-YY"))),"") | Q52: =IFERROR(IF(DATEVALUE(P52)>=DATEVALUE($EF$5),"",(TEXT(DATE(YEAR(P52),MONTH(P52)+1,DAY(P52)),"MMM-YY"))),"")
B53: KPI ID 25 R | C53: =IF(ISBLANK($D$6),"",(IFERROR(INDEX(Data!$C$7:$EE$39,MATCH($B53,Data!$C$7:$C$39,0),MATCH(C52,Data!$C$7:$EE$7,0)),""))) -> 30 | D53: =IF(ISBLANK($D$6),"",(IFERROR(INDEX(Data!$C$7:$EE$39,MATCH($B53,Data!$C$7:$C$39,0),MATCH(D52,Data!$C$7:$EE$7,0)),""))) -> 19 | E53: =IF(ISBLANK($D$6),"",(IFERROR(INDEX(Data!$C$7:$EE$39,MATCH($B53,Data!$C$7:$C$39,0),MATCH(E52,Data!$C$7:$EE$7,0)),""))) -> 31 | F53: =IF(ISBLANK($D$6),"",(IFERROR(INDEX(Data!$C$7:$EE$39,MATCH($B53,Data!$C$7:$C$39,0),MATCH(F52,Data!$C$7:$EE$7,0)),""))) -> 27 | G53: =IF(ISBLANK($D$6),"",(IFERROR(INDEX(Data!$C$7:$EE$39,MATCH($B53,Data!$C$7:$C$39,0),MATCH(G52,Data!$C$7:$EE$7,0)),""))) -> 18 | H53: =IF(ISBLANK($D$6),"",(IFERROR(INDEX(Data!$C$7:$EE$39,MATCH($B53,Data!$C$7:$C$39,0),MATCH(H52,Data!$C$7:$EE$7,0)),""))) -> 13 | I53: =IF(ISBLANK($D$6),"",(IFERROR(INDEX(Data!$C$7:$EE$39,MATCH($B53,Data!$C$7:$C$39,0),MATCH(I52,Data!$C$7:$EE$7,0)),""))) -> 24 | J53: =IF(ISBLANK($D$6),"",(IFERROR(INDEX(Data!$C$7:$EE$39,MATCH($B53,Data!$C$7:$C$39,0),MATCH(J52,Data!$C$7:$EE$7,0)),""))) -> 33 | ... M53: =IF(ISBLANK($D$6),"",(IFERROR(INDEX(Data!$C$7:$EE$39,MATCH($B53,Data!$C$7:$C$39,0),MATCH(M52,Data!$C$7:$EE$7,0)),""))) -> 4 | P53: =(IFERROR(INDEX(Data!$C$7:$EE$39,MATCH(#REF!,Data!$C$7:$C$39,0),MATCH(P$87,Data!$C$7:$EE$7,0)),"")) | Q53: =(IFERROR(INDEX(Data!$C$7:$EE$39,MATCH(#REF!,Data!$C$7:$C$39,0),MATCH(Q$87,Data!$C$7:$EE$7,0)),""))
B70: =VLOOKUP(B73, Data!$A$8:$B$200, 2, FALSE) -> Rekisteröityneiden asiakkaiden määrä
B72: Month and year | C72: =IF(ISBLANK($D$6),"",(TEXT(($D$6),"mmm-yy"))) -> Jun-26 | D72: =(TEXT(DATE(YEAR(C72),MONTH(C72)+1,DAY(C72)),"MMM-YY")) -> Jul-26 | E72: =(TEXT(DATE(YEAR(D72),MONTH(D72)+1,DAY(D72)),"MMM-YY")) -> Aug-26 | F72: =(TEXT(DATE(YEAR(E72),MONTH(E72)+1,DAY(E72)),"MMM-YY")) -> Sep-26 | G72: =(TEXT(DATE(YEAR(F72),MONTH(F72)+1,DAY(F72)),"MMM-YY")) -> Oct-26 | H72: =(TEXT(DATE(YEAR(G72),MONTH(G72)+1,DAY(G72)),"MMM-YY")) -> Nov-26 | I72: =(TEXT(DATE(YEAR(H72),MONTH(H72)+1,DAY(H72)),"MMM-YY")) -> Dec-26 | J72: =(TEXT(DATE(YEAR(I72),MONTH(I72)+1,DAY(I72)),"MMM-YY")) -> Jan-27 | K72: =(TEXT(DATE(YEAR(J72),MONTH(J72)+1,DAY(J72)),"MMM-YY")) -> Feb-27 | ... M72: =(TEXT(DATE(YEAR(L72),MONTH(L72)+1,DAY(L72)),"MMM-YY")) -> Apr-27 | P72: =IFERROR(IF(DATEVALUE(M72)>=DATEVALUE($EF$5),"",(TEXT(DATE(YEAR(M72),MONTH(M72)+1,DAY(M72)),"MMM-YY"))),"") | Q72: =IFERROR(IF(DATEVALUE(P72)>=DATEVALUE($EF$5),"",(TEXT(DATE(YEAR(P72),MONTH(P72)+1,DAY(P72)),"MMM-YY"))),"")
B73: KPI ID 1 | C73: =IF(ISBLANK($D$6),"",(IFERROR(INDEX(Data!$C$7:$EE$39,MATCH($B73,Data!$C$7:$C$39,0),MATCH(C72,Data!$C$7:$EE$7,0)),""))) -> 182 | D73: =IF(ISBLANK($D$6),"",(IFERROR(INDEX(Data!$C$7:$EE$39,MATCH($B73,Data!$C$7:$C$39,0),MATCH(D72,Data!$C$7:$EE$7,0)),""))) -> 186 | E73: =IF(ISBLANK($D$6),"",(IFERROR(INDEX(Data!$C$7:$EE$39,MATCH($B73,Data!$C$7:$C$39,0),MATCH(E72,Data!$C$7:$EE$7,0)),""))) -> 188 | F73: =IF(ISBLANK($D$6),"",(IFERROR(INDEX(Data!$C$7:$EE$39,MATCH($B73,Data!$C$7:$C$39,0),MATCH(F72,Data!$C$7:$EE$7,0)),""))) -> 196 | G73: =IF(ISBLANK($D$6),"",(IFERROR(INDEX(Data!$C$7:$EE$39,MATCH($B73,Data!$C$7:$C$39,0),MATCH(G72,Data!$C$7:$EE$7,0)),""))) -> 201 | H73: =IF(ISBLANK($D$6),"",(IFERROR(INDEX(Data!$C$7:$EE$39,MATCH($B73,Data!$C$7:$C$39,0),MATCH(H72,Data!$C$7:$EE$7,0)),""))) -> 210 | I73: =IF(ISBLANK($D$6),"",(IFERROR(INDEX(Data!$C$7:$EE$39,MATCH($B73,Data!$C$7:$C$39,0),MATCH(I72,Data!$C$7:$EE$7,0)),""))) -> 211 | J73: =IF(ISBLANK($D$6),"",(IFERROR(INDEX(Data!$C$7:$EE$39,MATCH($B73,Data!$C$7:$C$39,0),MATCH(J72,Data!$C$7:$EE$7,0)),""))) -> 213 | ... M73: =IF(ISBLANK($D$6),"",(IFERROR(INDEX(Data!$C$7:$EE$39,MATCH($B73,Data!$C$7:$C$39,0),MATCH(M72,Data!$C$7:$EE$7,0)),""))) -> 235 | P73: =(IFERROR(INDEX(Data!$C$7:$EE$39,MATCH(#REF!,Data!$C$7:$C$39,0),MATCH(P$87,Data!$C$7:$EE$7,0)),"")) | Q73: =(IFERROR(INDEX(Data!$C$7:$EE$39,MATCH(#REF!,Data!$C$7:$C$39,0),MATCH(Q$87,Data!$C$7:$EE$7,0)),""))
K91: Copyright: Veera Seaman

Sheet Data
C2: =Aloitus!$C$2 -> Kevät | H2: Lisää datasi alle. Voit antaa indikaattoreillesi omat koodit tai käyttää allaolevia. Älä käytä koodia useammin kuin kerran.
H3: Jos haluat vaihtaa aloitusvuoden, voit tehdä sen Listat-välilehdellä.
H4: Oma tuotteesi suunnitellaan omalla logollasi, valitsemillasi vöreillä ja tyylillä - tämä on vain esimerkki.
C6: =TEXT(TODAY(), "Mmmm") -> October | E6: =TEXT(TODAY(), "Yyyy") -> 2025
B7: Lisää indikaattoreiden nimet alle. | C7: Kuukausi ja vuosi | D7: =TEXT(DATE(Listat!$E$11, MONTH(1), DAY(1)), "Mmm-YY") -> Jan-25 | E7: =TEXT(DATE(YEAR(D7), MONTH(D7)+1, DAY(D7)), "Mmm-yy") -> Feb-25 | F7: =TEXT(DATE(YEAR(E7), MONTH(E7)+1, DAY(E7)), "Mmm-yy") -> Mar-25 | G7: =TEXT(DATE(YEAR(F7), MONTH(F7)+1, DAY(F7)), "Mmm-yy") -> Apr-25 | H7: =TEXT(DATE(YEAR(G7), MONTH(G7)+1, DAY(G7)), "Mmm-yy") -> May-25 | I7: =TEXT(DATE(YEAR(H7), MONTH(H7)+1, DAY(H7)), "Mmm-yy") -> Jun-25 | J7: =TEXT(DATE(YEAR(I7), MONTH(I7)+1, DAY(I7)), "Mmm-yy") -> Jul-25 | K7: =TEXT(DATE(YEAR(J7), MONTH(J7)+1, DAY(J7)), "Mmm-yy") -> Aug-25 | L7: =TEXT(DATE(YEAR(K7), MONTH(K7)+1, DAY(K7)), "Mmm-yy") -> Sep-25 | ... EE7: =TEXT(DATE(YEAR(ED7), MONTH(ED7)+1, DAY(ED7)), "Mmm-yy") -> Dec-35
A8: =IF(ISBLANK(C8), "", C8) -> KPI ID 1 | B8: Rekisteröityneiden asiakkaiden määrä | C8: KPI ID 1 | D8: =RANDBETWEEN(80, 100) -> 87 | E8: =D8+RANDBETWEEN(1, 10) -> 96 | F8: =E8+RANDBETWEEN(1, 10) -> 105 | G8: =F8+RANDBETWEEN(1, 10) -> 115 | H8: =G8+RANDBETWEEN(1, 10) -> 123 | I8: =H8+RANDBETWEEN(1, 10) -> 127 | J8: =I8+RANDBETWEEN(1, 10) -> 130 | K8: =J8+RANDBETWEEN(1, 10) -> 136 | L8: =K8+RANDBETWEEN(1, 10) -> 145 | ... EE8: =ED8+RANDBETWEEN(1, 10) -> 841
A9: =IF(ISBLANK(C9), "", C9) -> KPI ID 1 % | B9: Asiakkaiden määrän nousu edellisestä kuukaudesta | C9: KPI ID 1 % | D9: =D8/D8*100 -> 100 | E9: =(E8-D8)/D8*100 -> 10.344828 | F9: =(F8-E8)/E8*100 -> 9.375 | G9: =(G8-F8)/F8*100 -> 9.5238095 | H9: =(H8-G8)/G8*100 -> 6.9565217 | I9: =(I8-H8)/H8*100 -> 3.2520325 | J9: =(J8-I8)/I8*100 -> 2.3622047 | K9: =(K8-J8)/J8*100 -> 4.6153846 | L9: =(L8-K8)/K8*100 -> 6.6176471 | ... EE9: =(EE8-ED8)/ED8*100 -> 0.47789725
A10: =IF(ISBLANK(C10), "", C10) -> KPI ID 3 | B10: Asiakkaat, jotka vierailivat kaupassa toisen tai useamman kerran | C10: KPI ID 3 | D10: =RANDBETWEEN(1, 15) -> 12 | E10: =RANDBETWEEN(1, 15) -> 5 | F10: =RANDBETWEEN(1, 15) -> 13 | G10: =RANDBETWEEN(1, 15) -> 13 | H10: =RANDBETWEEN(1, 15) -> 5 | I10: =RANDBETWEEN(1, 15) -> 11 | J10: =RANDBETWEEN(1, 15) -> 13 | K10: =RANDBETWEEN(1, 15) -> 9 | ... EE10: =RANDBETWEEN(1, 15) -> 14
A11: =IF(ISBLANK(C11), "", C11) -> KPI ID 4 % | B11: Prosenttimäärä asiakkaita, jotka ostivat nallekarhun | C11: KPI ID 4 % | D11: =RAND() -> 0.53829888 | E11: =RAND() -> 0.018176375 | F11: =RAND() -> 0.24591894 | G11: =RAND() -> 0.54479014 | H11: =RAND() -> 0.68591405 | I11: =RAND() -> 0.14759101 | J11: =RAND() -> 0.042629189 | K11: =RAND() -> 0.74638066 | ... EE11: =RAND() -> 0.039203289
A12: =IF(ISBLANK(C12), "", C12) -> KPI ID 5 | B12: Nallekarhuja varastossa | C12: KPI ID 5 | D12: =RANDBETWEEN(1, 40) -> 5 | E12: =RANDBETWEEN(1, 40) -> 12 | F12: =RANDBETWEEN(1, 40) -> 29 | G12: =RANDBETWEEN(1, 40) -> 28 | H12: =RANDBETWEEN(1, 40) -> 7 | I12: =RANDBETWEEN(1, 40) -> 36 | J12: =RANDBETWEEN(1, 40) -> 38 | K12: =RANDBETWEEN(1, 40) -> 19 | ... EE12: =RANDBETWEEN(1, 40) -> 28
A13: =IF(ISBLANK(C13), "", C13) -> KPI ID 6 | B13: Punaisten rantapyyhkeiden määrä varastossa | C13: KPI ID 6 | D13: =RANDBETWEEN(1, 40) -> 3 | E13: =RANDBETWEEN(1, 40) -> 36 | F13: =RANDBETWEEN(1, 40) -> 22 | G13: =RANDBETWEEN(1, 40) -> 39 | H13: =RANDBETWEEN(1, 40) -> 31 | I13: =RANDBETWEEN(1, 40) -> 27 | J13: =RANDBETWEEN(1, 40) -> 7 | K13: =RANDBETWEEN(1, 40) -> 29 | ... EE13: =RANDBETWEEN(1, 40) -> 37
A14: =IF(ISBLANK(C14), "", C14) -> KPI ID 7 | B14: Vihreiden käsilaukkujen määrä varastossa | C14: KPI ID 7 | D14: =RANDBETWEEN(1, 40) -> 28 | E14: =RANDBETWEEN(1, 40) -> 18 | F14: =RANDBETWEEN(1, 40) -> 32 | G14: =RANDBETWEEN(1, 40) -> 26 | H14: =RANDBETWEEN(1, 40) -> 29 | I14: =RANDBETWEEN(1, 40) -> 26 | J14: =RANDBETWEEN(1, 40) -> 30 | K14: =RANDBETWEEN(1, 40) -> 24 | ... EE14: =RANDBETWEEN(1, 40) -> 10
A15: =IF(ISBLANK(C15), "", C15) -> KPI ID 8 % | B15: Virheellisten tuotteiden määrä koko inventaariosta (%) | C15: KPI ID 8 % | D15: =RAND() -> 0.94622326 | E15: =RAND() -> 0.036454979 | F15: =RAND() -> 0.86482075 | G15: =RAND() -> 0.73980273 | H15: =RAND() -> 0.27510649 | I15: =RAND() -> 0.5381416 | J15: =RAND() -> 0.81398872 | K15: =RAND() -> 0.80185238 | ... EE15: =RAND() -> 0.73238767
A16: =IF(ISBLANK(C16), "", C16) -> KPI ID 9 % | B16: Virheellisten tuotteiden määrä, jotka lähetettiin takaisin valmistajalle (%= | C16: KPI ID 9 % | D16: =RAND() -> 0.87090441 | E16: =RAND() -> 0.71062805 | F16: =RAND() -> 0.43161248 | G16: =RAND() -> 0.21964352 | H16: =RAND() -> 0.95383871 | I16: =RAND() -> 0.85921925 | J16: =RAND() -> 0.15603271 | K16: =RAND() -> 0.72446579 | ... EE16: =RAND() -> 0.3945075
A17: =IF(ISBLANK(C17), "", C17) -> KPI ID 10 | B17: Kokoaikaisten työntekijöiden määrä | C17: KPI ID 10 | D17: =RANDBETWEEN(1, 100) -> 6 | E17: =RANDBETWEEN(1, 100) -> 80 | F17: =RANDBETWEEN(1, 100) -> 4 | G17: =RANDBETWEEN(1, 100) -> 92 | H17: =RANDBETWEEN(1, 100) -> 92 | I17: =RANDBETWEEN(1, 100) -> 63 | J17: =RANDBETWEEN(1, 100) -> 15 | K17: =RANDBETWEEN(1, 100) -> 99 | ... EE17: =RANDBETWEEN(1, 100) -> 23
A18: =IF(ISBLANK(C18), "", C18) -> KPI ID 11 | B18: Osa-aikaisten työntekijöiden määrä | C18: KPI ID 11 | D18: =RANDBETWEEN(20, 45) -> 23 | E18: =RANDBETWEEN(20, 45) -> 44 | F18: =RANDBETWEEN(20, 45) -> 23 | G18: =RANDBETWEEN(20, 45) -> 36 | H18: =RANDBETWEEN(20, 45) -> 37 | I18: =RANDBETWEEN(20, 45) -> 26 | J18: =RANDBETWEEN(20, 45) -> 38 | K18: =RANDBETWEEN(20, 45) -> 43 | ... EE18: =RANDBETWEEN(20, 45) -> 28
A19: =IF(ISBLANK(C19), "", C19) -> KPI ID 12 % | B19: Osa-aikaiset työntekijät koko työvoimasta (%) | C19: KPI ID 12 % | D19: =RAND()+1 -> 1.0526568 | E19: =RAND()+1 -> 1.6865426 | F19: =RAND()+1 -> 1.6341481 | G19: =RAND()+1 -> 1.1052716 | H19: =RAND()+1 -> 1.4719038 | I19: =RAND()+1 -> 1.2865156 | J19: =RAND()+1 -> 1.9253925 | K19: =RAND()+1 -> 1.0924392 | ... EE19: =RAND()+1 -> 1.9841082
A20: =IF(ISBLANK(C20), "", C20) -> KPI ID 13 | B20: Työntekijöiden määrä | C20: KPI ID 13 | D20: =RANDBETWEEN(6, 10)+1.245 -> 11.245 | E20: =RANDBETWEEN(6, 10)+1.245 -> 7.245 | F20: =RANDBETWEEN(6, 10)+1.245 -> 9.245 | G20: =RANDBETWEEN(6, 10)+1.245 -> 9.245 | H20: =RANDBETWEEN(6, 10)+1.245 -> 9.245 | I20: =RANDBETWEEN(6, 10)+1.245 -> 7.245 | J20: =RANDBETWEEN(6, 10)+1.245 -> 8.245 | K20: =RANDBETWEEN(6, 10)+1.245 -> 7.245 | ... EE20: =RANDBETWEEN(6, 10)+1.245 -> 9.245
A21: =IF(ISBLANK(C21), "", C21) -> KPI ID 14 | B21: Esimerkki indikaattori | C21: KPI ID 14 | D21: =RANDBETWEEN(300, 440)+1.245 -> 322.245 | E21: =RANDBETWEEN(300, 440)+1.245 -> 391.245 | F21: =RANDBETWEEN(300, 440)+1.245 -> 435.245 | G21: =RANDBETWEEN(300, 440)+1.245 -> 380.245 | H21: =RANDBETWEEN(300, 440)+1.245 -> 375.245 | I21: =RANDBETWEEN(300, 440)+1.245 -> 316.245 | J21: =RANDBETWEEN(300, 440)+1.245 -> 383.245 | K21: =RANDBETWEEN(300, 440)+1.245 -> 351.245 | ... EE21: =RANDBETWEEN(300, 440)+1.245 -> 438.245
A22: =IF(ISBLANK(C22), "", C22) -> KPI ID 15 | B22: Esimerkki indikaattori | C22: KPI ID 15 | D22: =RAND() -> 0.40635263 | E22: =RAND() -> 0.72225977 | F22: =RAND() -> 0.386846 | G22: =RAND() -> 0.19812497 | H22: =RAND() -> 0.4478352 | I22: =RAND() -> 0.091623452 | J22: =RAND() -> 0.1858853 | K22: =RAND() -> 0.1322608 | ... EE22: =RAND() -> 0.22593371
A23: =IF(ISBLANK(C23), "", C23) -> KPI ID 16 % | B23: Esimerkki indikaattori | C23: KPI ID 16 % | D23: =RAND() -> 0.66519657 | E23: =RAND() -> 0.65351927 | F23: =RAND() -> 0.94392856 | G23: =RAND() -> 0.75542461 | H23: =RAND() -> 0.91444854 | I23: =RAND() -> 0.42971117 | J23: =RAND() -> 0.45934709 | K23: =RAND() -> 0.52484486 | ... EE23: =RAND() -> 0.49436944
A24: =IF(ISBLANK(C24), "", C24) -> KPI ID 17 | B24: Esimerkki indikaattori | C24: KPI ID 17 | D24: =RANDBETWEEN(1, 100) -> 14 | E24: =RANDBETWEEN(1, 100) -> 36 | F24: =RANDBETWEEN(1, 100) -> 74 | G24: =RANDBETWEEN(1, 100) -> 41 | H24: =RANDBETWEEN(1, 100) -> 16 | I24: =RANDBETWEEN(1, 100) -> 14 | J24: =RANDBETWEEN(1, 100) -> 46 | K24: =RANDBETWEEN(1, 100) -> 65 | ... EE24: =RANDBETWEEN(1, 100) -> 81
A25: =IF(ISBLANK(C25), "", C25) -> KPI ID 18 | B25: Esimerkki indikaattori | C25: KPI ID 18 | D25: =RANDBETWEEN(1, 200) -> 33 | E25: =RANDBETWEEN(1, 200) -> 24 | F25: =RANDBETWEEN(1, 200) -> 93 | G25: =RANDBETWEEN(1, 200) -> 97 | H25: =RANDBETWEEN(1, 200) -> 160 | I25: =RANDBETWEEN(1, 200) -> 166 | J25: =RANDBETWEEN(1, 200) -> 25 | K25: =RANDBETWEEN(1, 200) -> 170 | ... EE25: =RANDBETWEEN(1, 200) -> 81
A26: =IF(ISBLANK(C26), "", C26) -> KPI ID 19 % | B26: Esimerkki indikaattori | C26: KPI ID 19 % | D26: =RANDBETWEEN(20, 45) -> 42 | E26: =RANDBETWEEN(20, 45) -> 25 | F26: =RANDBETWEEN(20, 45) -> 27 | G26: =RANDBETWEEN(20, 45) -> 26 | H26: =RANDBETWEEN(20, 45) -> 27 | I26: =RANDBETWEEN(20, 45) -> 23 | J26: =RANDBETWEEN(20, 45) -> 21 | K26: =RANDBETWEEN(20, 45) -> 45 | ... DQ26: =RANDBETWEEN(20, 45) -> 22 | DR26: =RAND()+1 -> 1.6928378 | DS26: =RANDBETWEEN(20, 45) -> 44 | DT26: =RANDBETWEEN(20, 45) -> 42 | DU26: =RANDBETWEEN(20, 45) -> 25 | DV26: =RANDBETWEEN(20, 45) -> 43 | DW26: =RANDBETWEEN(20, 45) -> 27 | DX26: =RANDBETWEEN(20, 45) -> 39 | DY26: =RANDBETWEEN(20, 45) -> 25 | DZ26: =RANDBETWEEN(20, 45) -> 38 | ... EE26: =RANDBETWEEN(20, 45) -> 24
A27: =IF(ISBLANK(C27), "", C27) -> KPI ID 20 % | B27: Esimerkki indikaattori | C27: KPI ID 20 % | D27: =RAND()*0.224 -> 0.034231567 | E27: =RAND()*0.224 -> 0.13455097 | F27: =RAND()*0.224 -> 0.21092219 | G27: =RAND()*0.224 -> 0.20448427 | H27: =RAND()*0.224 -> 0.022597252 | I27: =RAND()*0.224 -> 0.044807585 | J27: =RAND()*0.224 -> 0.19577318 | K27: =RAND()*0.224 -> 0.10157329 | ... EE27: =RAND()*0.224 -> 0.010071972
A28: =IF(ISBLANK(C28), "", C28) -> KPI ID 21 % | B28: Esimerkki indikaattori | C28: KPI ID 21 % | D28: =RAND() -> 0.72448474 | E28: =RAND() -> 0.97532221 | F28: =RAND() -> 0.10584206 | G28: =RAND() -> 0.59692022 | H28: =RAND() -> 0.30374076 | I28: =RAND() -> 0.43371182 | J28: =RAND() -> 0.36308858 | K28: =RAND() -> 0.6400786 | ... EE28: =RAND() -> 0.93015494
A29: =IF(ISBLANK(C29), "", C29) -> KPI ID 22 | B29: Esimerkki indikaattori | C29: KPI ID 22 | D29: =RAND()+1 -> 1.6206484 | E29: =RAND()+1 -> 1.4792489 | F29: =RAND()+1 -> 1.0447674 | G29: =RAND()+1 -> 1.6733236 | H29: =RAND()+1 -> 1.1594876 | I29: =RAND()+1 -> 1.107296 | J29: =RAND()+1 -> 1.4594908 | K29: =RAND()+1 -> 1.8076096 | ... DP29: =RAND()+1 -> 1.5504773 | DQ29: =RANDBETWEEN(20, 45) -> 41 | DR29: =RAND()+1 -> 1.6276967 | DS29: =RAND()+1 -> 1.0494511 | DT29: =RAND()+1 -> 1.8043332 | DU29: =RAND()+1 -> 1.8823467 | DV29: =RAND()+1 -> 1.1698621 | DW29: =RAND()+1 -> 1.8966476 | DX29: =RAND()+1 -> 1.304241 | DY29: =RAND()+1 -> 1.3303123 | ... EE29: =RAND()+1 -> 1.0799549
A30: =IF(ISBLANK(C30), "", C30) -> KPI ID 23 R | B30: Esimerkki indikaattori | C30: KPI ID 23 R | D30: =RANDBETWEEN(1, 200) -> 92 | E30: =RANDBETWEEN(1, 200) -> 39 | F30: =RANDBETWEEN(1, 200) -> 186 | G30: =RANDBETWEEN(1, 200) -> 45 | H30: =RANDBETWEEN(1, 200) -> 19 | I30: =RANDBETWEEN(1, 200) -> 123 | J30: =RANDBETWEEN(1, 200) -> 33 | K30: =RANDBETWEEN(1, 200) -> 159 | ... EE30: =RANDBETWEEN(1, 200) -> 2
A31: =IF(ISBLANK(C31), "", C31) -> KPI ID 24 | B31: Esimerkki indikaattori | C31: KPI ID 24 | D31: =RANDBETWEEN(20, 45) -> 32 | E31: =RANDBETWEEN(20, 45) -> 21 | F31: =RANDBETWEEN(20, 45) -> 33 | G31: =RANDBETWEEN(20, 45) -> 38 | H31: =RANDBETWEEN(20, 45) -> 45 | I31: =RANDBETWEEN(20, 45) -> 25 | J31: =RANDBETWEEN(20, 45) -> 39 | K31: =RANDBETWEEN(20, 45) -> 45 | ... DM31: =RANDBETWEEN(20, 45) -> 29 | DN31: =RAND()+1 -> 1.3978559 | DO31: =RANDBETWEEN(20, 45) -> 25 | DP31: =RANDBETWEEN(20, 45) -> 35 | DQ31: =RANDBETWEEN(20, 45) -> 30 | DR31: =RANDBETWEEN(20, 45) -> 42 | DS31: =RANDBETWEEN(20, 45) -> 39 | DT31: =RANDBETWEEN(20, 45) -> 38 | DU31: =RANDBETWEEN(20, 45) -> 21 | DV31: =RANDBETWEEN(20, 45) -> 38 | ... ED31: =RANDBETWEEN(20, 45) -> 29 | EE31: =RAND() -> 0.9602549
A32: =IF(ISBLANK(C32), "", C32) -> KPI ID 25 R | B32: Esimerkki indikaattori | C32: KPI ID 25 R | D32: =RANDBETWEEN(1, 33) -> 10 | E32: =RANDBETWEEN(1, 33) -> 1 | F32: =RANDBETWEEN(1, 33) -> 9 | G32: =RANDBETWEEN(1, 33) -> 2 | H32: =RANDBETWEEN(1, 33) -> 31 | I32: =RANDBETWEEN(1, 33) -> 6 | J32: =RANDBETWEEN(1, 33) -> 28 | K32: =RANDBETWEEN(1, 33) -> 22 | ... EE32: =RANDBETWEEN(1, 33) -> 29
A33: =IF(ISBLANK(C33), "", C33) -> KPI ID 26 | B33: Esimerkki indikaattori | C33: KPI ID 26 | D33: =RANDBETWEEN(0, 45) -> 18 | E33: =RANDBETWEEN(0, 45) -> 26 | F33: =RANDBETWEEN(0, 45) -> 4 | G33: =RANDBETWEEN(0, 45) -> 32 | H33: =RANDBETWEEN(0, 45) -> 16 | I33: =RANDBETWEEN(0, 45) -> 27 | J33: =RANDBETWEEN(0, 45) -> 3 | K33: =RANDBETWEEN(0, 45) -> 19 | ... EE33: =RANDBETWEEN(0, 45) -> 18
A34: =IF(ISBLANK(C34), "", C34) -> KPI ID 27 | B34: Esimerkki indikaattori | C34: KPI ID 27 | D34: =RAND() -> 0.60838298 | E34: =RAND() -> 0.71096645 | F34: =RAND() -> 0.042295219 | G34: =RAND() -> 0.84436106 | H34: =RAND() -> 0.50068912 | I34: =RAND() -> 0.39254907 | J34: =RAND() -> 0.085679822 | K34: =RAND() -> 0.91785618 | ... EE34: =RAND() -> 0.84818056
A35: =IF(ISBLANK(C35), "", C35) -> KPI ID 28 % | B35: Esimerkki indikaattori | C35: KPI ID 28 % | D35: =RAND()+1 -> 1.8912873 | E35: =RAND()+1 -> 1.2626006 | F35: =RAND()+1 -> 1.1565963 | G35: =RAND()+1 -> 1.663201 | H35: =RAND()+1 -> 1.8903018 | I35: =RAND()+1 -> 1.4484857 | J35: =RAND()+1 -> 1.9739256 | K35: =RAND()+1 -> 1.4208075 | ... EE35: =RAND()+1 -> 1.8474067
A36: =IF(ISBLANK(C36), "", C36) -> KPI ID 29 % | B36: Esimerkki indikaattori | C36: KPI ID 29 % | D36: =RANDBETWEEN(20, 45) -> 28 | E36: =RANDBETWEEN(20, 45) -> 27 | F36: =RANDBETWEEN(20, 45) -> 35 | G36: =RANDBETWEEN(20, 45) -> 29 | H36: =RANDBETWEEN(20, 45) -> 20 | I36: =RANDBETWEEN(20, 45) -> 23 | J36: =RANDBETWEEN(20, 45) -> 43 | K36: =RANDBETWEEN(20, 45) -> 38 | ... EE36: =RANDBETWEEN(20, 45) -> 21
A37: =IF(ISBLANK(C37), "", C37) -> KPI ID 30 | B37: Esimerkki indikaattori | C37: KPI ID 30 | D37: =RANDBETWEEN(20, 45) -> 27 | E37: =RANDBETWEEN(20, 45) -> 39 | F37: =RANDBETWEEN(20, 45) -> 29 | G37: =RANDBETWEEN(20, 45) -> 40 | H37: =RANDBETWEEN(20, 45) -> 29 | I37: =RANDBETWEEN(20, 45) -> 22 | J37: =RANDBETWEEN(20, 45) -> 35 | K37: =RANDBETWEEN(20, 45) -> 21 | ... DN37: =RANDBETWEEN(20, 45) -> 29 | DO37: =RAND()+1 -> 1.0995637 | DP37: =RANDBETWEEN(20, 45) -> 40 | DQ37: =RANDBETWEEN(20, 45) -> 43 | DR37: =RANDBETWEEN(20, 45) -> 23 | DS37: =RANDBETWEEN(20, 45) -> 42 | DT37: =RANDBETWEEN(20, 45) -> 32 | DU37: =RANDBETWEEN(20, 45) -> 25 | DV37: =RANDBETWEEN(20, 45) -> 32 | DW37: =RANDBETWEEN(20, 45) -> 44 | ... ED37: =RANDBETWEEN(20, 45) -> 25 | EE37: =RAND() -> 0.79154233
A38: =IF(ISBLANK(C38), "", C38) -> KPI ID 31 R | B38: Esimerkki indikaattori | C38: KPI ID 31 R | D38: =RANDBETWEEN(20, 45) -> 24 | E38: =RANDBETWEEN(20, 45) -> 42 | F38: =RANDBETWEEN(20, 45) -> 35 | G38: =RANDBETWEEN(20, 45) -> 20 | H38: =RANDBETWEEN(20, 45) -> 41 | I38: =RANDBETWEEN(20, 45) -> 42 | J38: =RANDBETWEEN(20, 45) -> 36 | K38: =RANDBETWEEN(20, 45) -> 33 | ... EE38: =RANDBETWEEN(20, 45) -> 45
A39: =IF(ISBLANK(C39), "", C39) -> KPI ID 32 | B39: Esimerkki indikaattori | C39: KPI ID 32 | D39: {=_xlfn.RANDARRAY()} -> 0.34662402 | E39: {=_xlfn.RANDARRAY()} -> 0.22514754 | F39: {=_xlfn.RANDARRAY()} -> 0.98876861 | G39: {=_xlfn.RANDARRAY()} -> 0.7263791 | H39: {=_xlfn.RANDARRAY()} -> 0.23020272 | I39: {=_xlfn.RANDARRAY()} -> 0.13458381 | J39: {=_xlfn.RANDARRAY()} -> 0.086514178 | K39: {=_xlfn.RANDARRAY()} -> 0.49359342 | ... DN39: {=_xlfn.RANDARRAY()} -> 0.16014871 | DO39: =RANDBETWEEN(20, 45) -> 38 | DP39: {=_xlfn.RANDARRAY()} -> 0.10357569 | DQ39: {=_xlfn.RANDARRAY()} -> 0.61565004 | DR39: {=_xlfn.RANDARRAY()} -> 0.31186638 | DS39: {=_xlfn.RANDARRAY()} -> 0.28034251 | DT39: {=_xlfn.RANDARRAY()} -> 0.34644873 | DU39: {=_xlfn.RANDARRAY()} -> 0.92745467 | DV39: {=_xlfn.RANDARRAY()} -> 0.98765337 | DW39: {=_xlfn.RANDARRAY()} -> 0.23460396 | ... EE39: {=_xlfn.RANDARRAY()} -> 0.60208771
A40: =IF(ISBLANK(C40), "", C40)
A41: =IF(ISBLANK(C41), "", C41)
A42: =IF(ISBLANK(C42), "", C42)
...

Sheet Ota yhteyttä
B3: Ota yhteyttä sähköpostitse:
B5: veeraseaman@gmail.com
