Workbook
Name Colours: 'Set-up'!$D$2:$G$2

Sheet Set-up
B2: Choose your colour scheme: | C2: Spring | D2: Header | E2: Highlight | G2: Copyright
B4: Add your logo (please resize to fit):

Sheet Lists
C2: ='Set-up'!$C$2 -> Spring
C7: =TEXT(TODAY(), "Mmmm") -> October | D7: =TEXT(TODAY(), "Yyyy") -> 2025
C8: To set up the list below, please write the start year (replace the current year with the year your data count starts from): | F8: 2020
B10: # | C10: Month | E10: Year | F10: Year calculation (do not edit)
B11: 0 | C11: =TEXT(TODAY(), "Mmmm") -> October | E11: =F8 -> 2020 | F11: =E11-$D$7 -> -5
B12: 1 | C12: =TEXT(DATE(YEAR(TODAY()),MONTH(TODAY())+B12,DAY(TODAY())), "Mmmm") -> November | E12: =E11+1 -> 2021 | F12: =E12-$D$7 -> -4
B13: 2 | C13: =TEXT(DATE(YEAR(TODAY()),MONTH(TODAY())+B13,DAY(TODAY())), "Mmmm") -> December | E13: =E12+1 -> 2022 | F13: =E13-$D$7 -> -3
B14: 3 | C14: =TEXT(DATE(YEAR(TODAY()),MONTH(TODAY())+B14,DAY(TODAY())), "Mmmm") -> January | E14: =E13+1 -> 2023 | F14: =E14-$D$7 -> -2
B15: 4 | C15: =TEXT(DATE(YEAR(TODAY()),MONTH(TODAY())+B15,DAY(TODAY())), "Mmmm") -> February | E15: =E14+1 -> 2024 | F15: =E15-$D$7 -> -1
B16: 5 | C16: =TEXT(DATE(YEAR(TODAY()),MONTH(TODAY())+B16,DAY(TODAY())), "Mmmm") -> March | E16: =E15+1 -> 2025 | F16: =E16-$D$7 -> 0
B17: 6 | C17: =TEXT(DATE(YEAR(TODAY()),MONTH(TODAY())+B17,DAY(TODAY())), "Mmmm") -> April | E17: =E16+1 -> 2026 | F17: =E17-$D$7 -> 1
B18: 7 | C18: =TEXT(DATE(YEAR(TODAY()),MONTH(TODAY())+B18,DAY(TODAY())), "Mmmm") -> May | E18: =E17+1 -> 2027 | F18: =E18-$D$7 -> 2
B19: 8 | C19: =TEXT(DATE(YEAR(TODAY()),MONTH(TODAY())+B19,DAY(TODAY())), "Mmmm") -> June | E19: =E18+1 -> 2028 | F19: =E19-$D$7 -> 3
B20: 9 | C20: =TEXT(DATE(YEAR(TODAY()),MONTH(TODAY())+B20,DAY(TODAY())), "Mmmm") -> July | E20: =E19+1 -> 2029 | F20: =E20-$D$7 -> 4
B21: 10 | C21: =TEXT(DATE(YEAR(TODAY()),MONTH(TODAY())+B21,DAY(TODAY())), "Mmmm") -> August | E21: =E20+1 -> 2030 | F21: =E21-$D$7 -> 5
B22: 11 | C22: =TEXT(DATE(YEAR(TODAY()),MONTH(TODAY())+B22,DAY(TODAY())), "Mmmm") -> September | E22: =E21+1 -> 2031 | F22: =E22-$D$7 -> 6
E23: =E22+1 -> 2032 | F23: =E23-$D$7 -> 7
E24: =E23+1 -> 2033 | F24: =E24-$D$7 -> 8
E25: =E24+1 -> 2034 | F25: =E25-$D$7 -> 9
E26: =E25+1 -> 2035 | F26: =E26-$D$7 -> 10

Sheet Dashboard
C2: ='Set-up'!$C$2 -> Spring
D6: =TEXT(($C$7&" "&$C$8),"MMm-YY") -> Jan-20
B7: Select month to view: | C7: January
B8: Select year to view: | C8: 2020
B10: =VLOOKUP(B13, Raw!$A$8:$B$200, 2, FALSE) -> Percentage of faulty items of all stock
B12: Month and year | C12: =IF(ISBLANK($D$6),"",(TEXT(($D$6),"mmm-yy"))) -> Jan-20 | D12: =(TEXT(DATE(YEAR(C12),MONTH(C12)+1,DAY(C12)),"MMM-YY")) -> Feb-20 | E12: =(TEXT(DATE(YEAR(D12),MONTH(D12)+1,DAY(D12)),"MMM-YY")) -> Mar-20 | F12: =(TEXT(DATE(YEAR(E12),MONTH(E12)+1,DAY(E12)),"MMM-YY")) -> Apr-20 | G12: =(TEXT(DATE(YEAR(F12),MONTH(F12)+1,DAY(F12)),"MMM-YY")) -> May-20 | H12: =(TEXT(DATE(YEAR(G12),MONTH(G12)+1,DAY(G12)),"MMM-YY")) -> Jun-20 | I12: =(TEXT(DATE(YEAR(H12),MONTH(H12)+1,DAY(H12)),"MMM-YY")) -> Jul-20 | J12: =(TEXT(DATE(YEAR(I12),MONTH(I12)+1,DAY(I12)),"MMM-YY")) -> Aug-20 | K12: =(TEXT(DATE(YEAR(J12),MONTH(J12)+1,DAY(J12)),"MMM-YY")) -> Sep-20 | ... M12: =(TEXT(DATE(YEAR(L12),MONTH(L12)+1,DAY(L12)),"MMM-YY")) -> Nov-20 | P12: =IFERROR(IF(DATEVALUE(M12)>=DATEVALUE($EF$5),"",(TEXT(DATE(YEAR(M12),MONTH(M12)+1,DAY(M12)),"MMM-YY"))),"") | Q12: =IFERROR(IF(DATEVALUE(P12)>=DATEVALUE($EF$5),"",(TEXT(DATE(YEAR(P12),MONTH(P12)+1,DAY(P12)),"MMM-YY"))),"")
B13: KPI ID 8 % | C13: =IF(ISBLANK($D$6),"",(IFERROR(INDEX(Raw!$C$7:$EE$39,MATCH($B13,Raw!$C$7:$C$39,0),MATCH(C12,Raw!$C$7:$EE$7,0)),""))) -> 0.15283629 | D13: =IF(ISBLANK($D$6),"",(IFERROR(INDEX(Raw!$C$7:$EE$39,MATCH($B13,Raw!$C$7:$C$39,0),MATCH(D12,Raw!$C$7:$EE$7,0)),""))) -> 0.052625395 | E13: =IF(ISBLANK($D$6),"",(IFERROR(INDEX(Raw!$C$7:$EE$39,MATCH($B13,Raw!$C$7:$C$39,0),MATCH(E12,Raw!$C$7:$EE$7,0)),""))) -> 0.36283128 | F13: =IF(ISBLANK($D$6),"",(IFERROR(INDEX(Raw!$C$7:$EE$39,MATCH($B13,Raw!$C$7:$C$39,0),MATCH(F12,Raw!$C$7:$EE$7,0)),""))) -> 0.55850276 | G13: =IF(ISBLANK($D$6),"",(IFERROR(INDEX(Raw!$C$7:$EE$39,MATCH($B13,Raw!$C$7:$C$39,0),MATCH(G12,Raw!$C$7:$EE$7,0)),""))) -> 0.31004621 | H13: =IF(ISBLANK($D$6),"",(IFERROR(INDEX(Raw!$C$7:$EE$39,MATCH($B13,Raw!$C$7:$C$39,0),MATCH(H12,Raw!$C$7:$EE$7,0)),""))) -> 0.24997184 | I13: =IF(ISBLANK($D$6),"",(IFERROR(INDEX(Raw!$C$7:$EE$39,MATCH($B13,Raw!$C$7:$C$39,0),MATCH(I12,Raw!$C$7:$EE$7,0)),""))) -> 0.93529106 | J13: =IF(ISBLANK($D$6),"",(IFERROR(INDEX(Raw!$C$7:$EE$39,MATCH($B13,Raw!$C$7:$C$39,0),MATCH(J12,Raw!$C$7:$EE$7,0)),""))) -> 0.0091832864 | ... M13: =IF(ISBLANK($D$6),"",(IFERROR(INDEX(Raw!$C$7:$EE$39,MATCH($B13,Raw!$C$7:$C$39,0),MATCH(M12,Raw!$C$7:$EE$7,0)),""))) -> 0.1139581 | P13: =(IFERROR(INDEX(Raw!$C$7:$EE$39,MATCH(#REF!,Raw!$C$7:$C$39,0),MATCH(P$87,Raw!$C$7:$EE$7,0)),"")) | Q13: =(IFERROR(INDEX(Raw!$C$7:$EE$39,MATCH(#REF!,Raw!$C$7:$C$39,0),MATCH(Q$87,Raw!$C$7:$EE$7,0)),""))
B30: =VLOOKUP(B33, Raw!$A$8:$B$200, 2, FALSE) -> Number of red beach towels in stock
B32: Month and year | C32: =IF(ISBLANK($D$6),"",(TEXT(($D$6),"mmm-yy"))) -> Jan-20 | D32: =(TEXT(DATE(YEAR(C32),MONTH(C32)+1,DAY(C32)),"MMM-YY")) -> Feb-20 | E32: =(TEXT(DATE(YEAR(D32),MONTH(D32)+1,DAY(D32)),"MMM-YY")) -> Mar-20 | F32: =(TEXT(DATE(YEAR(E32),MONTH(E32)+1,DAY(E32)),"MMM-YY")) -> Apr-20 | G32: =(TEXT(DATE(YEAR(F32),MONTH(F32)+1,DAY(F32)),"MMM-YY")) -> May-20 | H32: =(TEXT(DATE(YEAR(G32),MONTH(G32)+1,DAY(G32)),"MMM-YY")) -> Jun-20 | I32: =(TEXT(DATE(YEAR(H32),MONTH(H32)+1,DAY(H32)),"MMM-YY")) -> Jul-20 | J32: =(TEXT(DATE(YEAR(I32),MONTH(I32)+1,DAY(I32)),"MMM-YY")) -> Aug-20 | K32: =(TEXT(DATE(YEAR(J32),MONTH(J32)+1,DAY(J32)),"MMM-YY")) -> Sep-20 | ... M32: =(TEXT(DATE(YEAR(L32),MONTH(L32)+1,DAY(L32)),"MMM-YY")) -> Nov-20 | P32: =IFERROR(IF(DATEVALUE(M32)>=DATEVALUE($EF$5),"",(TEXT(DATE(YEAR(M32),MONTH(M32)+1,DAY(M32)),"MMM-YY"))),"") | Q32: =IFERROR(IF(DATEVALUE(P32)>=DATEVALUE($EF$5),"",(TEXT(DATE(YEAR(P32),MONTH(P32)+1,DAY(P32)),"MMM-YY"))),"")
B33: KPI ID 6 | C33: =IF(ISBLANK($D$6),"",(IFERROR(INDEX(Raw!$C$7:$EE$39,MATCH($B33,Raw!$C$7:$C$39,0),MATCH(C32,Raw!$C$7:$EE$7,0)),""))) -> 15 | D33: =IF(ISBLANK($D$6),"",(IFERROR(INDEX(Raw!$C$7:$EE$39,MATCH($B33,Raw!$C$7:$C$39,0),MATCH(D32,Raw!$C$7:$EE$7,0)),""))) -> 32 | E33: =IF(ISBLANK($D$6),"",(IFERROR(INDEX(Raw!$C$7:$EE$39,MATCH($B33,Raw!$C$7:$C$39,0),MATCH(E32,Raw!$C$7:$EE$7,0)),""))) -> 40 | F33: =IF(ISBLANK($D$6),"",(IFERROR(INDEX(Raw!$C$7:$EE$39,MATCH($B33,Raw!$C$7:$C$39,0),MATCH(F32,Raw!$C$7:$EE$7,0)),""))) -> 25 | G33: =IF(ISBLANK($D$6),"",(IFERROR(INDEX(Raw!$C$7:$EE$39,MATCH($B33,Raw!$C$7:$C$39,0),MATCH(G32,Raw!$C$7:$EE$7,0)),""))) -> 24 | H33: =IF(ISBLANK($D$6),"",(IFERROR(INDEX(Raw!$C$7:$EE$39,MATCH($B33,Raw!$C$7:$C$39,0),MATCH(H32,Raw!$C$7:$EE$7,0)),""))) -> 3 | I33: =IF(ISBLANK($D$6),"",(IFERROR(INDEX(Raw!$C$7:$EE$39,MATCH($B33,Raw!$C$7:$C$39,0),MATCH(I32,Raw!$C$7:$EE$7,0)),""))) -> 39 | J33: =IF(ISBLANK($D$6),"",(IFERROR(INDEX(Raw!$C$7:$EE$39,MATCH($B33,Raw!$C$7:$C$39,0),MATCH(J32,Raw!$C$7:$EE$7,0)),""))) -> 12 | ... M33: =IF(ISBLANK($D$6),"",(IFERROR(INDEX(Raw!$C$7:$EE$39,MATCH($B33,Raw!$C$7:$C$39,0),MATCH(M32,Raw!$C$7:$EE$7,0)),""))) -> 18 | P33: =(IFERROR(INDEX(Raw!$C$7:$EE$39,MATCH(#REF!,Raw!$C$7:$C$39,0),MATCH(P$87,Raw!$C$7:$EE$7,0)),"")) | Q33: =(IFERROR(INDEX(Raw!$C$7:$EE$39,MATCH(#REF!,Raw!$C$7:$C$39,0),MATCH(Q$87,Raw!$C$7:$EE$7,0)),""))
B50: =VLOOKUP(B53, Raw!$A$8:$B$200, 2, FALSE) -> Example indicator
B52: Month and year | C52: =IF(ISBLANK($D$6),"",(TEXT(($D$6),"mmm-yy"))) -> Jan-20 | D52: =(TEXT(DATE(YEAR(C52),MONTH(C52)+1,DAY(C52)),"MMM-YY")) -> Feb-20 | E52: =(TEXT(DATE(YEAR(D52),MONTH(D52)+1,DAY(D52)),"MMM-YY")) -> Mar-20 | F52: =(TEXT(DATE(YEAR(E52),MONTH(E52)+1,DAY(E52)),"MMM-YY")) -> Apr-20 | G52: =(TEXT(DATE(YEAR(F52),MONTH(F52)+1,DAY(F52)),"MMM-YY")) -> May-20 | H52: =(TEXT(DATE(YEAR(G52),MONTH(G52)+1,DAY(G52)),"MMM-YY")) -> Jun-20 | I52: =(TEXT(DATE(YEAR(H52),MONTH(H52)+1,DAY(H52)),"MMM-YY")) -> Jul-20 | J52: =(TEXT(DATE(YEAR(I52),MONTH(I52)+1,DAY(I52)),"MMM-YY")) -> Aug-20 | K52: =(TEXT(DATE(YEAR(J52),MONTH(J52)+1,DAY(J52)),"MMM-YY")) -> Sep-20 | ... M52: =(TEXT(DATE(YEAR(L52),MONTH(L52)+1,DAY(L52)),"MMM-YY")) -> Nov-20 | P52: =IFERROR(IF(DATEVALUE(M52)>=DATEVALUE($EF$5),"",(TEXT(DATE(YEAR(M52),MONTH(M52)+1,DAY(M52)),"MMM-YY"))),"") | Q52: =IFERROR(IF(DATEVALUE(P52)>=DATEVALUE($EF$5),"",(TEXT(DATE(YEAR(P52),MONTH(P52)+1,DAY(P52)),"MMM-YY"))),"")
B53: KPI ID 25 R | C53: =IF(ISBLANK($D$6),"",(IFERROR(INDEX(Raw!$C$7:$EE$39,MATCH($B53,Raw!$C$7:$C$39,0),MATCH(C52,Raw!$C$7:$EE$7,0)),""))) -> 12 | D53: =IF(ISBLANK($D$6),"",(IFERROR(INDEX(Raw!$C$7:$EE$39,MATCH($B53,Raw!$C$7:$C$39,0),MATCH(D52,Raw!$C$7:$EE$7,0)),""))) -> 10 | E53: =IF(ISBLANK($D$6),"",(IFERROR(INDEX(Raw!$C$7:$EE$39,MATCH($B53,Raw!$C$7:$C$39,0),MATCH(E52,Raw!$C$7:$EE$7,0)),""))) -> 22 | F53: =IF(ISBLANK($D$6),"",(IFERROR(INDEX(Raw!$C$7:$EE$39,MATCH($B53,Raw!$C$7:$C$39,0),MATCH(F52,Raw!$C$7:$EE$7,0)),""))) -> 6 | G53: =IF(ISBLANK($D$6),"",(IFERROR(INDEX(Raw!$C$7:$EE$39,MATCH($B53,Raw!$C$7:$C$39,0),MATCH(G52,Raw!$C$7:$EE$7,0)),""))) -> 16 | H53: =IF(ISBLANK($D$6),"",(IFERROR(INDEX(Raw!$C$7:$EE$39,MATCH($B53,Raw!$C$7:$C$39,0),MATCH(H52,Raw!$C$7:$EE$7,0)),""))) -> 25 | I53: =IF(ISBLANK($D$6),"",(IFERROR(INDEX(Raw!$C$7:$EE$39,MATCH($B53,Raw!$C$7:$C$39,0),MATCH(I52,Raw!$C$7:$EE$7,0)),""))) -> 30 | J53: =IF(ISBLANK($D$6),"",(IFERROR(INDEX(Raw!$C$7:$EE$39,MATCH($B53,Raw!$C$7:$C$39,0),MATCH(J52,Raw!$C$7:$EE$7,0)),""))) -> 8 | ... M53: =IF(ISBLANK($D$6),"",(IFERROR(INDEX(Raw!$C$7:$EE$39,MATCH($B53,Raw!$C$7:$C$39,0),MATCH(M52,Raw!$C$7:$EE$7,0)),""))) -> 27 | P53: =(IFERROR(INDEX(Raw!$C$7:$EE$39,MATCH(#REF!,Raw!$C$7:$C$39,0),MATCH(P$87,Raw!$C$7:$EE$7,0)),"")) | Q53: =(IFERROR(INDEX(Raw!$C$7:$EE$39,MATCH(#REF!,Raw!$C$7:$C$39,0),MATCH(Q$87,Raw!$C$7:$EE$7,0)),""))
B70: =VLOOKUP(B73, Raw!$A$8:$B$200, 2, FALSE) -> Number of registered customers
B72: Month and year | C72: =IF(ISBLANK($D$6),"",(TEXT(($D$6),"mmm-yy"))) -> Jan-20 | D72: =(TEXT(DATE(YEAR(C72),MONTH(C72)+1,DAY(C72)),"MMM-YY")) -> Feb-20 | E72: =(TEXT(DATE(YEAR(D72),MONTH(D72)+1,DAY(D72)),"MMM-YY")) -> Mar-20 | F72: =(TEXT(DATE(YEAR(E72),MONTH(E72)+1,DAY(E72)),"MMM-YY")) -> Apr-20 | G72: =(TEXT(DATE(YEAR(F72),MONTH(F72)+1,DAY(F72)),"MMM-YY")) -> May-20 | H72: =(TEXT(DATE(YEAR(G72),MONTH(G72)+1,DAY(G72)),"MMM-YY")) -> Jun-20 | I72: =(TEXT(DATE(YEAR(H72),MONTH(H72)+1,DAY(H72)),"MMM-YY")) -> Jul-20 | J72: =(TEXT(DATE(YEAR(I72),MONTH(I72)+1,DAY(I72)),"MMM-YY")) -> Aug-20 | K72: =(TEXT(DATE(YEAR(J72),MONTH(J72)+1,DAY(J72)),"MMM-YY")) -> Sep-20 | ... M72: =(TEXT(DATE(YEAR(L72),MONTH(L72)+1,DAY(L72)),"MMM-YY")) -> Nov-20 | P72: =IFERROR(IF(DATEVALUE(M72)>=DATEVALUE($EF$5),"",(TEXT(DATE(YEAR(M72),MONTH(M72)+1,DAY(M72)),"MMM-YY"))),"") | Q72: =IFERROR(IF(DATEVALUE(P72)>=DATEVALUE($EF$5),"",(TEXT(DATE(YEAR(P72),MONTH(P72)+1,DAY(P72)),"MMM-YY"))),"")
B73: KPI ID 1 | C73: =IF(ISBLANK($D$6),"",(IFERROR(INDEX(Raw!$C$7:$EE$39,MATCH($B73,Raw!$C$7:$C$39,0),MATCH(C72,Raw!$C$7:$EE$7,0)),""))) -> 97 | D73: =IF(ISBLANK($D$6),"",(IFERROR(INDEX(Raw!$C$7:$EE$39,MATCH($B73,Raw!$C$7:$C$39,0),MATCH(D72,Raw!$C$7:$EE$7,0)),""))) -> 98 | E73: =IF(ISBLANK($D$6),"",(IFERROR(INDEX(Raw!$C$7:$EE$39,MATCH($B73,Raw!$C$7:$C$39,0),MATCH(E72,Raw!$C$7:$EE$7,0)),""))) -> 99 | F73: =IF(ISBLANK($D$6),"",(IFERROR(INDEX(Raw!$C$7:$EE$39,MATCH($B73,Raw!$C$7:$C$39,0),MATCH(F72,Raw!$C$7:$EE$7,0)),""))) -> 107 | G73: =IF(ISBLANK($D$6),"",(IFERROR(INDEX(Raw!$C$7:$EE$39,MATCH($B73,Raw!$C$7:$C$39,0),MATCH(G72,Raw!$C$7:$EE$7,0)),""))) -> 115 | H73: =IF(ISBLANK($D$6),"",(IFERROR(INDEX(Raw!$C$7:$EE$39,MATCH($B73,Raw!$C$7:$C$39,0),MATCH(H72,Raw!$C$7:$EE$7,0)),""))) -> 125 | I73: =IF(ISBLANK($D$6),"",(IFERROR(INDEX(Raw!$C$7:$EE$39,MATCH($B73,Raw!$C$7:$C$39,0),MATCH(I72,Raw!$C$7:$EE$7,0)),""))) -> 126 | J73: =IF(ISBLANK($D$6),"",(IFERROR(INDEX(Raw!$C$7:$EE$39,MATCH($B73,Raw!$C$7:$C$39,0),MATCH(J72,Raw!$C$7:$EE$7,0)),""))) -> 127 | ... M73: =IF(ISBLANK($D$6),"",(IFERROR(INDEX(Raw!$C$7:$EE$39,MATCH($B73,Raw!$C$7:$C$39,0),MATCH(M72,Raw!$C$7:$EE$7,0)),""))) -> 144 | P73: =(IFERROR(INDEX(Raw!$C$7:$EE$39,MATCH(#REF!,Raw!$C$7:$C$39,0),MATCH(P$87,Raw!$C$7:$EE$7,0)),"")) | Q73: =(IFERROR(INDEX(Raw!$C$7:$EE$39,MATCH(#REF!,Raw!$C$7:$C$39,0),MATCH(Q$87,Raw!$C$7:$EE$7,0)),""))
K91: Copyright: Veera Seaman

Sheet Raw
C2: ='Set-up'!$C$2 -> Spring | H2: Insert your data here. You can give your indicators their own identifier (KPI ID) or use the ones listed below.
H3: If you want to change the start year, please do so in the Lists tab.
H4: If you would like more options, such as define the start month, please contact me (You will find my contact details in the Contact tab).
C6: =TEXT(TODAY(), "Mmmm") -> October | E6: =TEXT(TODAY(), "Yyyy") -> 2025
B7: Add your indicator names below: | C7: Month and year | D7: =TEXT(DATE(Lists!$E$11, MONTH(1), DAY(1)), "Mmm-YY") -> Jan-20 | E7: =TEXT(DATE(YEAR(D7), MONTH(D7)+1, DAY(D7)), "Mmm-yy") -> Feb-20 | F7: =TEXT(DATE(YEAR(E7), MONTH(E7)+1, DAY(E7)), "Mmm-yy") -> Mar-20 | G7: =TEXT(DATE(YEAR(F7), MONTH(F7)+1, DAY(F7)), "Mmm-yy") -> Apr-20 | H7: =TEXT(DATE(YEAR(G7), MONTH(G7)+1, DAY(G7)), "Mmm-yy") -> May-20 | I7: =TEXT(DATE(YEAR(H7), MONTH(H7)+1, DAY(H7)), "Mmm-yy") -> Jun-20 | J7: =TEXT(DATE(YEAR(I7), MONTH(I7)+1, DAY(I7)), "Mmm-yy") -> Jul-20 | K7: =TEXT(DATE(YEAR(J7), MONTH(J7)+1, DAY(J7)), "Mmm-yy") -> Aug-20 | L7: =TEXT(DATE(YEAR(K7), MONTH(K7)+1, DAY(K7)), "Mmm-yy") -> Sep-20 | ... EE7: =TEXT(DATE(YEAR(ED7), MONTH(ED7)+1, DAY(ED7)), "Mmm-yy") -> Dec-30
A8: =IF(ISBLANK(C8), "", C8) -> KPI ID 1 | B8: Number of registered customers | C8: KPI ID 1 | D8: =RANDBETWEEN(80, 100) -> 97 | E8: =D8+RANDBETWEEN(1, 10) -> 98 | F8: =E8+RANDBETWEEN(1, 10) -> 99 | G8: =F8+RANDBETWEEN(1, 10) -> 107 | H8: =G8+RANDBETWEEN(1, 10) -> 115 | I8: =H8+RANDBETWEEN(1, 10) -> 125 | J8: =I8+RANDBETWEEN(1, 10) -> 126 | K8: =J8+RANDBETWEEN(1, 10) -> 127 | L8: =K8+RANDBETWEEN(1, 10) -> 131 | ... EE8: =ED8+RANDBETWEEN(1, 10) -> 817
A9: =IF(ISBLANK(C9), "", C9) -> KPI ID 1 % | B9: Percentage of customer base growth from previous month | C9: KPI ID 1 % | D9: =D8/D8*100 -> 100 | E9: =(E8-D8)/D8*100 -> 1.0309278 | F9: =(F8-E8)/E8*100 -> 1.0204082 | G9: =(G8-F8)/F8*100 -> 8.0808081 | H9: =(H8-G8)/G8*100 -> 7.4766355 | I9: =(I8-H8)/H8*100 -> 8.6956522 | J9: =(J8-I8)/I8*100 -> 0.8 | K9: =(K8-J8)/J8*100 -> 0.79365079 | L9: =(L8-K8)/K8*100 -> 3.1496063 | ... EE9: =(EE8-ED8)/ED8*100 -> 0.73982737
A10: =IF(ISBLANK(C10), "", C10) -> KPI ID 3 | B10: Number of customers visiting store for a second of subsequent time | C10: KPI ID 3 | D10: =RANDBETWEEN(1, 15) -> 11 | E10: =RANDBETWEEN(1, 15) -> 11 | F10: =RANDBETWEEN(1, 15) -> 9 | G10: =RANDBETWEEN(1, 15) -> 14 | H10: =RANDBETWEEN(1, 15) -> 12 | I10: =RANDBETWEEN(1, 15) -> 3 | J10: =RANDBETWEEN(1, 15) -> 11 | K10: =RANDBETWEEN(1, 15) -> 10 | ... EE10: =RANDBETWEEN(1, 15) -> 8
A11: =IF(ISBLANK(C11), "", C11) -> KPI ID 4 % | B11: Percentage of customers buying teddy bears | C11: KPI ID 4 % | D11: =RAND() -> 0.23534505 | E11: =RAND() -> 0.29395531 | F11: =RAND() -> 0.49634921 | G11: =RAND() -> 0.4848654 | H11: =RAND() -> 0.6693741 | I11: =RAND() -> 0.72050386 | J11: =RAND() -> 0.47997229 | K11: =RAND() -> 0.79397676 | ... EE11: =RAND() -> 0.86260002
A12: =IF(ISBLANK(C12), "", C12) -> KPI ID 5 | B12: Number of teddy bears in stock | C12: KPI ID 5 | D12: =RANDBETWEEN(1, 40) -> 8 | E12: =RANDBETWEEN(1, 40) -> 8 | F12: =RANDBETWEEN(1, 40) -> 13 | G12: =RANDBETWEEN(1, 40) -> 1 | H12: =RANDBETWEEN(1, 40) -> 34 | I12: =RANDBETWEEN(1, 40) -> 12 | J12: =RANDBETWEEN(1, 40) -> 25 | K12: =RANDBETWEEN(1, 40) -> 33 | ... EE12: =RANDBETWEEN(1, 40) -> 21
A13: =IF(ISBLANK(C13), "", C13) -> KPI ID 6 | B13: Number of red beach towels in stock | C13: KPI ID 6 | D13: =RANDBETWEEN(1, 40) -> 15 | E13: =RANDBETWEEN(1, 40) -> 32 | F13: =RANDBETWEEN(1, 40) -> 40 | G13: =RANDBETWEEN(1, 40) -> 25 | H13: =RANDBETWEEN(1, 40) -> 24 | I13: =RANDBETWEEN(1, 40) -> 3 | J13: =RANDBETWEEN(1, 40) -> 39 | K13: =RANDBETWEEN(1, 40) -> 12 | ... EE13: =RANDBETWEEN(1, 40) -> 20
A14: =IF(ISBLANK(C14), "", C14) -> KPI ID 7 | B14: Number of green handbacks in stock | C14: KPI ID 7 | D14: =RANDBETWEEN(1, 40) -> 10 | E14: =RANDBETWEEN(1, 40) -> 10 | F14: =RANDBETWEEN(1, 40) -> 23 | G14: =RANDBETWEEN(1, 40) -> 10 | H14: =RANDBETWEEN(1, 40) -> 26 | I14: =RANDBETWEEN(1, 40) -> 10 | J14: =RANDBETWEEN(1, 40) -> 35 | K14: =RANDBETWEEN(1, 40) -> 24 | ... EE14: =RANDBETWEEN(1, 40) -> 13
A15: =IF(ISBLANK(C15), "", C15) -> KPI ID 8 % | B15: Percentage of faulty items of all stock | C15: KPI ID 8 % | D15: =RAND() -> 0.15283629 | E15: =RAND() -> 0.052625395 | F15: =RAND() -> 0.36283128 | G15: =RAND() -> 0.55850276 | H15: =RAND() -> 0.31004621 | I15: =RAND() -> 0.24997184 | J15: =RAND() -> 0.93529106 | K15: =RAND() -> 0.0091832864 | ... EE15: =RAND() -> 0.34270634
A16: =IF(ISBLANK(C16), "", C16) -> KPI ID 9 % | B16: Percentage of faulty items sent back to manufacturer | C16: KPI ID 9 % | D16: =RAND() -> 0.32233956 | E16: =RAND() -> 0.28867499 | F16: =RAND() -> 0.35164942 | G16: =RAND() -> 0.93510702 | H16: =RAND() -> 0.91438974 | I16: =RAND() -> 0.8283339 | J16: =RAND() -> 0.25309989 | K16: =RAND() -> 0.47938966 | ... EE16: =RAND() -> 0.030564294
A17: =IF(ISBLANK(C17), "", C17) -> KPI ID 10 | B17: Number of full-time employees | C17: KPI ID 10 | D17: =RANDBETWEEN(1, 100) -> 7 | E17: =RANDBETWEEN(1, 100) -> 6 | F17: =RANDBETWEEN(1, 100) -> 40 | G17: =RANDBETWEEN(1, 100) -> 85 | H17: =RANDBETWEEN(1, 100) -> 61 | I17: =RANDBETWEEN(1, 100) -> 36 | J17: =RANDBETWEEN(1, 100) -> 25 | K17: =RANDBETWEEN(1, 100) -> 63 | ... EE17: =RANDBETWEEN(1, 100) -> 33
A18: =IF(ISBLANK(C18), "", C18) -> KPI ID 11 | B18: Number of part-fime employees | C18: KPI ID 11 | D18: =RANDBETWEEN(20, 45) -> 32 | E18: =RANDBETWEEN(20, 45) -> 28 | F18: =RANDBETWEEN(20, 45) -> 23 | G18: =RANDBETWEEN(20, 45) -> 27 | H18: =RANDBETWEEN(20, 45) -> 41 | I18: =RANDBETWEEN(20, 45) -> 40 | J18: =RANDBETWEEN(20, 45) -> 37 | K18: =RANDBETWEEN(20, 45) -> 34 | ... EE18: =RANDBETWEEN(20, 45) -> 44
A19: =IF(ISBLANK(C19), "", C19) -> KPI ID 12 % | B19: Percentage of part-time employees of all employees | C19: KPI ID 12 % | D19: =RAND()+1 -> 1.3375783 | E19: =RAND()+1 -> 1.0332342 | F19: =RAND()+1 -> 1.4947093 | G19: =RAND()+1 -> 1.0216181 | H19: =RAND()+1 -> 1.6154261 | I19: =RAND()+1 -> 1.1533847 | J19: =RAND()+1 -> 1.7529198 | K19: =RAND()+1 -> 1.3310491 | ... EE19: =RAND()+1 -> 1.1545858
A20: =IF(ISBLANK(C20), "", C20) -> KPI ID 13 | B20: Number of all employees | C20: KPI ID 13 | D20: =RANDBETWEEN(6, 10)+1.245 -> 7.245 | E20: =RANDBETWEEN(6, 10)+1.245 -> 10.245 | F20: =RANDBETWEEN(6, 10)+1.245 -> 8.245 | G20: =RANDBETWEEN(6, 10)+1.245 -> 7.245 | H20: =RANDBETWEEN(6, 10)+1.245 -> 11.245 | I20: =RANDBETWEEN(6, 10)+1.245 -> 10.245 | J20: =RANDBETWEEN(6, 10)+1.245 -> 7.245 | K20: =RANDBETWEEN(6, 10)+1.245 -> 11.245 | ... EE20: =RANDBETWEEN(6, 10)+1.245 -> 9.245
A21: =IF(ISBLANK(C21), "", C21) -> KPI ID 14 | B21: Example indicator | C21: KPI ID 14 | D21: =RANDBETWEEN(300, 440)+1.245 -> 436.245 | E21: =RANDBETWEEN(300, 440)+1.245 -> 333.245 | F21: =RANDBETWEEN(300, 440)+1.245 -> 303.245 | G21: =RANDBETWEEN(300, 440)+1.245 -> 394.245 | H21: =RANDBETWEEN(300, 440)+1.245 -> 427.245 | I21: =RANDBETWEEN(300, 440)+1.245 -> 388.245 | J21: =RANDBETWEEN(300, 440)+1.245 -> 343.245 | K21: =RANDBETWEEN(300, 440)+1.245 -> 412.245 | ... EE21: =RANDBETWEEN(300, 440)+1.245 -> 379.245
A22: =IF(ISBLANK(C22), "", C22) -> KPI ID 15 | B22: Example indicator | C22: KPI ID 15 | D22: =RAND() -> 0.95922838 | E22: =RAND() -> 0.56230755 | F22: =RAND() -> 0.90723964 | G22: =RAND() -> 0.86369065 | H22: =RAND() -> 0.43508564 | I22: =RAND() -> 0.011610968 | J22: =RAND() -> 0.57441163 | K22: =RAND() -> 0.86154847 | ... EE22: =RAND() -> 0.59175676
A23: =IF(ISBLANK(C23), "", C23) -> KPI ID 16 % | B23: Percentage of value 1 of value 2 | C23: KPI ID 16 % | D23: =RAND() -> 0.4579552 | E23: =RAND() -> 0.78400131 | F23: =RAND() -> 0.54511858 | G23: =RAND() -> 0.86066811 | H23: =RAND() -> 0.79263417 | I23: =RAND() -> 0.4004203 | J23: =RAND() -> 0.87015349 | K23: =RAND() -> 0.9190061 | ... EE23: =RAND() -> 0.059720032
A24: =IF(ISBLANK(C24), "", C24) -> KPI ID 17 | B24: Example indicator | C24: KPI ID 17 | D24: =RANDBETWEEN(1, 100) -> 8 | E24: =RANDBETWEEN(1, 100) -> 85 | F24: =RANDBETWEEN(1, 100) -> 76 | G24: =RANDBETWEEN(1, 100) -> 84 | H24: =RANDBETWEEN(1, 100) -> 82 | I24: =RANDBETWEEN(1, 100) -> 25 | J24: =RANDBETWEEN(1, 100) -> 95 | K24: =RANDBETWEEN(1, 100) -> 5 | ... EE24: =RANDBETWEEN(1, 100) -> 21
A25: =IF(ISBLANK(C25), "", C25) -> KPI ID 18 | B25: Example indicator | C25: KPI ID 18 | D25: =RANDBETWEEN(1, 200) -> 38 | E25: =RANDBETWEEN(1, 200) -> 77 | F25: =RANDBETWEEN(1, 200) -> 187 | G25: =RANDBETWEEN(1, 200) -> 16 | H25: =RANDBETWEEN(1, 200) -> 96 | I25: =RANDBETWEEN(1, 200) -> 93 | J25: =RANDBETWEEN(1, 200) -> 153 | K25: =RANDBETWEEN(1, 200) -> 50 | ... EE25: =RANDBETWEEN(1, 200) -> 139
A26: =IF(ISBLANK(C26), "", C26) -> KPI ID 19 % | B26: Example indicator | C26: KPI ID 19 % | D26: =RANDBETWEEN(20, 45) -> 21 | E26: =RANDBETWEEN(20, 45) -> 42 | F26: =RANDBETWEEN(20, 45) -> 45 | G26: =RANDBETWEEN(20, 45) -> 30 | H26: =RANDBETWEEN(20, 45) -> 34 | I26: =RANDBETWEEN(20, 45) -> 24 | J26: =RANDBETWEEN(20, 45) -> 28 | K26: =RANDBETWEEN(20, 45) -> 20 | ... DQ26: =RANDBETWEEN(20, 45) -> 34 | DR26: =RAND()+1 -> 1.1201623 | DS26: =RANDBETWEEN(20, 45) -> 32 | DT26: =RANDBETWEEN(20, 45) -> 41 | DU26: =RANDBETWEEN(20, 45) -> 36 | DV26: =RANDBETWEEN(20, 45) -> 27 | DW26: =RANDBETWEEN(20, 45) -> 45 | DX26: =RANDBETWEEN(20, 45) -> 21 | DY26: =RANDBETWEEN(20, 45) -> 34 | DZ26: =RANDBETWEEN(20, 45) -> 35 | ... EE26: =RANDBETWEEN(20, 45) -> 20
A27: =IF(ISBLANK(C27), "", C27) -> KPI ID 20 % | B27: Example indicator | C27: KPI ID 20 % | D27: =RAND()*0.224 -> 0.13794108 | E27: =RAND()*0.224 -> 0.19544719 | F27: =RAND()*0.224 -> 0.17645605 | G27: =RAND()*0.224 -> 0.10572275 | H27: =RAND()*0.224 -> 0.16019233 | I27: =RAND()*0.224 -> 0.21236091 | J27: =RAND()*0.224 -> 0.12573814 | K27: =RAND()*0.224 -> 0.01768668 | ... EE27: =RAND()*0.224 -> 0.13315555
A28: =IF(ISBLANK(C28), "", C28) -> KPI ID 21 % | B28: Example indicator | C28: KPI ID 21 % | D28: =RAND() -> 0.40600245 | E28: =RAND() -> 0.16802939 | F28: =RAND() -> 0.35444637 | G28: =RAND() -> 0.057229308 | H28: =RAND() -> 0.64208707 | I28: =RAND() -> 0.63040873 | J28: =RAND() -> 0.36806199 | K28: =RAND() -> 0.53109845 | ... EE28: =RAND() -> 0.66499432
A29: =IF(ISBLANK(C29), "", C29) -> KPI ID 22 | B29: Example indicator | C29: KPI ID 22 | D29: =RAND()+1 -> 1.9423225 | E29: =RAND()+1 -> 1.5214165 | F29: =RAND()+1 -> 1.2730593 | G29: =RAND()+1 -> 1.5184138 | H29: =RAND()+1 -> 1.0132827 | I29: =RAND()+1 -> 1.7961888 | J29: =RAND()+1 -> 1.3197856 | K29: =RAND()+1 -> 1.2838418 | ... DP29: =RAND()+1 -> 1.5329168 | DQ29: =RANDBETWEEN(20, 45) -> 30 | DR29: =RAND()+1 -> 1.1398893 | DS29: =RAND()+1 -> 1.8110773 | DT29: =RAND()+1 -> 1.7041467 | DU29: =RAND()+1 -> 1.5525374 | DV29: =RAND()+1 -> 1.9612887 | DW29: =RAND()+1 -> 1.0824065 | DX29: =RAND()+1 -> 1.5339078 | DY29: =RAND()+1 -> 1.7687863 | ... EE29: =RAND()+1 -> 1.9560706
A30: =IF(ISBLANK(C30), "", C30) -> KPI ID 23 R | B30: Example indicator | C30: KPI ID 23 R | D30: =RANDBETWEEN(1, 200) -> 11 | E30: =RANDBETWEEN(1, 200) -> 93 | F30: =RANDBETWEEN(1, 200) -> 23 | G30: =RANDBETWEEN(1, 200) -> 153 | H30: =RANDBETWEEN(1, 200) -> 184 | I30: =RANDBETWEEN(1, 200) -> 4 | J30: =RANDBETWEEN(1, 200) -> 168 | K30: =RANDBETWEEN(1, 200) -> 57 | ... EE30: =RANDBETWEEN(1, 200) -> 96
A31: =IF(ISBLANK(C31), "", C31) -> KPI ID 24 | B31: Example indicator | C31: KPI ID 24 | D31: =RANDBETWEEN(20, 45) -> 42 | E31: =RANDBETWEEN(20, 45) -> 28 | F31: =RANDBETWEEN(20, 45) -> 36 | G31: =RANDBETWEEN(20, 45) -> 20 | H31: =RANDBETWEEN(20, 45) -> 28 | I31: =RANDBETWEEN(20, 45) -> 33 | J31: =RANDBETWEEN(20, 45) -> 38 | K31: =RANDBETWEEN(20, 45) -> 42 | ... DM31: =RANDBETWEEN(20, 45) -> 24 | DN31: =RAND()+1 -> 1.2846458 | DO31: =RANDBETWEEN(20, 45) -> 35 | DP31: =RANDBETWEEN(20, 45) -> 37 | DQ31: =RANDBETWEEN(20, 45) -> 25 | DR31: =RANDBETWEEN(20, 45) -> 45 | DS31: =RANDBETWEEN(20, 45) -> 32 | DT31: =RANDBETWEEN(20, 45) -> 30 | DU31: =RANDBETWEEN(20, 45) -> 30 | DV31: =RANDBETWEEN(20, 45) -> 31 | ... ED31: =RANDBETWEEN(20, 45) -> 31 | EE31: =RAND() -> 0.48372209
A32: =IF(ISBLANK(C32), "", C32) -> KPI ID 25 R | B32: Example indicator | C32: KPI ID 25 R | D32: =RANDBETWEEN(1, 33) -> 12 | E32: =RANDBETWEEN(1, 33) -> 10 | F32: =RANDBETWEEN(1, 33) -> 22 | G32: =RANDBETWEEN(1, 33) -> 6 | H32: =RANDBETWEEN(1, 33) -> 16 | I32: =RANDBETWEEN(1, 33) -> 25 | J32: =RANDBETWEEN(1, 33) -> 30 | K32: =RANDBETWEEN(1, 33) -> 8 | ... EE32: =RANDBETWEEN(1, 33) -> 3
A33: =IF(ISBLANK(C33), "", C33) -> KPI ID 26 | B33: Example indicator | C33: KPI ID 26 | D33: =RANDBETWEEN(0, 45) -> 1 | E33: =RANDBETWEEN(0, 45) -> 30 | F33: =RANDBETWEEN(0, 45) -> 9 | G33: =RANDBETWEEN(0, 45) -> 0 | H33: =RANDBETWEEN(0, 45) -> 36 | I33: =RANDBETWEEN(0, 45) -> 28 | J33: =RANDBETWEEN(0, 45) -> 16 | K33: =RANDBETWEEN(0, 45) -> 2 | ... EE33: =RANDBETWEEN(0, 45) -> 33
A34: =IF(ISBLANK(C34), "", C34) -> KPI ID 27 | B34: Example indicator | C34: KPI ID 27 | D34: =RAND() -> 0.45821395 | E34: =RAND() -> 0.60713273 | F34: =RAND() -> 0.27424102 | G34: =RAND() -> 0.96559966 | H34: =RAND() -> 0.73084252 | I34: =RAND() -> 0.62891305 | J34: =RAND() -> 0.32826222 | K34: =RAND() -> 0.56433775 | ... EE34: =RAND() -> 0.15004216
A35: =IF(ISBLANK(C35), "", C35) -> KPI ID 28 % | B35: Example indicator | C35: KPI ID 28 % | D35: =RAND()+1 -> 1.0576844 | E35: =RAND()+1 -> 1.1754841 | F35: =RAND()+1 -> 1.6988801 | G35: =RAND()+1 -> 1.2679495 | H35: =RAND()+1 -> 1.9278424 | I35: =RAND()+1 -> 1.1589981 | J35: =RAND()+1 -> 1.2809801 | K35: =RAND()+1 -> 1.7470353 | ... EE35: =RAND()+1 -> 1.3551312
A36: =IF(ISBLANK(C36), "", C36) -> KPI ID 29 % | B36: Example indicator | C36: KPI ID 29 % | D36: =RANDBETWEEN(20, 45) -> 34 | E36: =RANDBETWEEN(20, 45) -> 29 | F36: =RANDBETWEEN(20, 45) -> 44 | G36: =RANDBETWEEN(20, 45) -> 20 | H36: =RANDBETWEEN(20, 45) -> 38 | I36: =RANDBETWEEN(20, 45) -> 29 | J36: =RANDBETWEEN(20, 45) -> 27 | K36: =RANDBETWEEN(20, 45) -> 41 | ... EE36: =RANDBETWEEN(20, 45) -> 21
A37: =IF(ISBLANK(C37), "", C37) -> KPI ID 30 | B37: Example indicator | C37: KPI ID 30 | D37: =RANDBETWEEN(20, 45) -> 35 | E37: =RANDBETWEEN(20, 45) -> 34 | F37: =RANDBETWEEN(20, 45) -> 25 | G37: =RANDBETWEEN(20, 45) -> 22 | H37: =RANDBETWEEN(20, 45) -> 43 | I37: =RANDBETWEEN(20, 45) -> 40 | J37: =RANDBETWEEN(20, 45) -> 21 | K37: =RANDBETWEEN(20, 45) -> 22 | ... DN37: =RANDBETWEEN(20, 45) -> 31 | DO37: =RAND()+1 -> 1.7280351 | DP37: =RANDBETWEEN(20, 45) -> 38 | DQ37: =RANDBETWEEN(20, 45) -> 25 | DR37: =RANDBETWEEN(20, 45) -> 27 | DS37: =RANDBETWEEN(20, 45) -> 25 | DT37: =RANDBETWEEN(20, 45) -> 38 | DU37: =RANDBETWEEN(20, 45) -> 23 | DV37: =RANDBETWEEN(20, 45) -> 32 | DW37: =RANDBETWEEN(20, 45) -> 41 | ... ED37: =RANDBETWEEN(20, 45) -> 21 | EE37: =RAND() -> 0.23326647
A38: =IF(ISBLANK(C38), "", C38) -> KPI ID 31 R | B38: Example indicator | C38: KPI ID 31 R | D38: =RANDBETWEEN(20, 45) -> 41 | E38: =RANDBETWEEN(20, 45) -> 45 | F38: =RANDBETWEEN(20, 45) -> 24 | G38: =RANDBETWEEN(20, 45) -> 28 | H38: =RANDBETWEEN(20, 45) -> 29 | I38: =RANDBETWEEN(20, 45) -> 35 | J38: =RANDBETWEEN(20, 45) -> 27 | K38: =RANDBETWEEN(20, 45) -> 37 | ... EE38: =RANDBETWEEN(20, 45) -> 26
A39: =IF(ISBLANK(C39), "", C39) -> KPI ID 32 | B39: Example indicator | C39: KPI ID 32 | D39: {=_xlfn.RANDARRAY()} -> 0.64856447 | E39: {=_xlfn.RANDARRAY()} -> 0.14156854 | F39: {=_xlfn.RANDARRAY()} -> 0.55299765 | G39: {=_xlfn.RANDARRAY()} -> 0.77176093 | H39: {=_xlfn.RANDARRAY()} -> 0.82343563 | I39: {=_xlfn.RANDARRAY()} -> 0.83590152 | J39: {=_xlfn.RANDARRAY()} -> 0.0046342472 | K39: {=_xlfn.RANDARRAY()} -> 0.48643851 | ... DN39: {=_xlfn.RANDARRAY()} -> 0.57415163 | DO39: =RANDBETWEEN(20, 45) -> 40 | DP39: {=_xlfn.RANDARRAY()} -> 0.3973729 | DQ39: {=_xlfn.RANDARRAY()} -> 0.25439647 | DR39: {=_xlfn.RANDARRAY()} -> 0.075487062 | DS39: {=_xlfn.RANDARRAY()} -> 0.44562578 | DT39: {=_xlfn.RANDARRAY()} -> 0.68227773 | DU39: {=_xlfn.RANDARRAY()} -> 0.50068237 | DV39: {=_xlfn.RANDARRAY()} -> 0.74760936 | DW39: {=_xlfn.RANDARRAY()} -> 0.51116627 | ... EE39: {=_xlfn.RANDARRAY()} -> 0.59820607
A40: =IF(ISBLANK(C40), "", C40)
A41: =IF(ISBLANK(C41), "", C41)
A42: =IF(ISBLANK(C42), "", C42)
...

Sheet Contact
B3: Please contact me to discuss dashboard / dataset solutions for your small or medium sized business.
B5: veeraseaman@gmail.com
